Workbook

Sheet ReadMe
A1: Azure OpenAI Capacity & Cost Sizing Workbook
A3: Purpose | B3: Size PAYGO cost vs Provisioned Throughput (PTU) requirements per use case, with aggregation by model + PTU deployment type.
A5: How to use
A6: 1. | B6: Catalog sheet: verify/edit model throughput + pricing metrics and PTU rates (blue cells = inputs).
A7: 2. | B7: LoadPeriods sheet: define up to 3 load periods (name, hours/day, days/week).
A8: 3. | B8: UseCases sheet: one row per use case - model, deployment types, tokens/request, cache %, RPM per period.
A9: 4. | B9: Calcs sheet: per-use-case results (auto). Summary sheet: PTU groups + PayGO vs PTU comparison (auto).
A11: Method
A12: PayGO $/mo | B12: Sum over periods of: [fresh input x input rate + cached input x cached rate + output x output rate] x deployment multiplier / 1M
A13: Normalized TPM | B13: input TPM x (1 - cache rate) + output TPM x output ratio (cached tokens are deducted 100% from PTU utilization)
A14: PTUs required | B14: peak normalized TPM / model Input-TPM-per-PTU, rounded up to the deployment minimum / increment
A15: Utilization | B15: normalized token-minutes used / deployed capacity across 730.5 h month
A16: Assumption | B16: PTU groups assume coincident peaks across use cases sharing a model+deployment (worst case).
A18: Sources (July 2026)
A19: PTU throughput & minimums | B19: learn.microsoft.com/azure/foundry/openai/how-to/provisioned-throughput-onboarding (ms.date 2026-04-29)
A20: PTU sizing methodology | B20: learn.microsoft.com/azure/foundry/openai/concepts/provisioned-throughput
A21: PAYGO prices | B21: azure.microsoft.com/pricing/details/azure-openai (Global Standard base; verify region uplifts)
A22: Caution | B22: Prices and PTU rates change. Validate with the Azure pricing calculator and Foundry capacity calculator before committing.

Sheet Catalog
A1: Model & Deployment Metrics (inputs in blue)
A3: Model | B3: Input TPM per PTU | C3: Output ratio (out:in) | D3: Min PTU Global/DZ | E3: Incr Global/DZ | F3: Min PTU Regional | G3: Incr Regional | H3: Input $/1M | I3: Cached input $/1M | J3: Output $/1M | K3: Notes
A4: gpt-5.5 | B4: 1200 | C4: 6 | D4: 15 | E4: 5 | F4: 50 | G4: 50 | H4: 5 | I4: 0.5 | J4: 30
A5: gpt-5.4 | B5: 2400 | C5: 6 | D5: 15 | E5: 5 | F5: 50 | G5: 50 | H5: 2.5 | I5: 0.25 | J5: 15
A6: gpt-5.4-mini | B6: 7900 | C6: 8 | D6: 15 | E6: 5 | F6: 25 | G6: 25 | H6: 0.45 | I6: 0.045 | J6: 3.6 | K6: ESTIMATE - verify
A7: gpt-5.2 | B7: 3400 | C7: 8 | D7: 15 | E7: 5 | F7: 50 | G7: 50 | H7: 1.75 | I7: 0.175 | J7: 14
A8: gpt-5.1 | B8: 4750 | C8: 8 | D8: 15 | E8: 5 | F8: 50 | G8: 50 | H8: 1.25 | I8: 0.125 | J8: 10 | K8: ESTIMATE - verify
A9: gpt-5 | B9: 4750 | C9: 8 | D9: 15 | E9: 5 | F9: 50 | G9: 50 | H9: 1.25 | I9: 0.125 | J9: 10
A10: gpt-5-mini | B10: 23750 | C10: 8 | D10: 15 | E10: 5 | F10: 25 | G10: 25 | H10: 0.25 | I10: 0.025 | J10: 2
A11: gpt-4.1 | B11: 3000 | C11: 4 | D11: 15 | E11: 5 | F11: 50 | G11: 50 | H11: 2 | I11: 0.5 | J11: 8
A12: gpt-4.1-mini | B12: 14900 | C12: 4 | D12: 15 | E12: 5 | F12: 25 | G12: 25 | H12: 0.4 | I12: 0.1 | J12: 1.6
A13: gpt-4.1-nano | B13: 59400 | C13: 4 | D13: 15 | E13: 5 | F13: 25 | G13: 25 | H13: 0.1 | I13: 0.025 | J13: 0.4
A14: gpt-4o | B14: 2500 | C14: 4 | D14: 15 | E14: 5 | F14: 50 | G14: 50 | H14: 2.5 | I14: 1.25 | J14: 10
A15: gpt-4o-mini | B15: 37000 | C15: 4 | D15: 15 | E15: 5 | F15: 25 | G15: 25 | H15: 0.15 | I15: 0.075 | J15: 0.6
A16: o3 | B16: 3000 | C16: 4 | D16: 15 | E16: 5 | F16: 50 | G16: 50 | H16: 2 | I16: 0.5 | J16: 8
A17: o4-mini | B17: 5400 | C17: 4 | D17: 15 | E17: 5 | F17: 25 | G17: 25 | H17: 1.1 | I17: 0.275 | J17: 4.4
A26: PTU rates ($ per PTU)
A27: Deployment type | B27: Hourly $/PTU/hr | C27: Monthly resv $/PTU | D27: Yearly resv $/PTU
A28: Global | B28: 1 | C28: 260 | D28: 2652
A29: Data Zone | B29: 1.1 | C29: 286 | D29: 2916.6
A30: Regional | B30: 2 | C30: 520 | D30: 5304
A33: PAYGO price multiplier vs Global Standard
A34: Deployment type | B34: Multiplier
A35: Global | B35: 1
A36: Data Zone | B36: 1.1
A37: Regional | B37: 1.2
A39: Weeks per month | B39: =365.25/7/12 -> 4.3482143
A40: Hours per month | B40: =8766/12 -> 730.5

Sheet LoadPeriods
A1: Load Periods (inputs in blue)
A3: Period name | B3: Hours per day | C3: Days per week | D3: Hours per week | E3: Hours per month
A4: Weekday - Business Hours | B4: 10 | C4: 5 | D4: =B4*C4 -> 50 | E4: =D4*Catalog!$B$39 -> 217.41071
A5: Weekday - Off-Peak | B5: 14 | C5: 5 | D5: =B5*C5 -> 70 | E5: =D5*Catalog!$B$39 -> 304.375
A6: Weekend - Whole Day | B6: 24 | C6: 2 | D6: =B6*C6 -> 48 | E6: =D6*Catalog!$B$39 -> 208.71429
D7: Total | E7: =SUM(E4:E6) -> 730.5

Sheet UseCases
A1: Use Cases (inputs in blue). RPM = average requests/min sustained during each period.
A3: Use case | B3: Model | C3: PayGO deployment | D3: PTU deployment | E3: Input tokens/req | F3: Output tokens/req | G3: Cache rate % | H3: =LoadPeriods!A4&" RPM" -> Weekday - Business Hours RPM | I3: =LoadPeriods!A5&" RPM" -> Weekday - Off-Peak RPM | J3: =LoadPeriods!A6&" RPM" -> Weekend - Whole Day RPM
A4: RAG Chat | B4: gpt-5 | C4: Global | D4: Global | E4: 3500 | F4: 300 | G4: 0.3 | H4: 75 | I4: 10 | J4: 10
A5: Summarization | B5: gpt-5 | C5: Global | D5: Global | E5: 5000 | F5: 300 | G5: 0.1 | H5: 75 | I5: 10 | J5: 10
A6: Classification | B6: gpt-5-mini | C6: Global | D6: Global | E6: 3800 | F6: 10 | G6: 0.5 | H6: 75 | I6: 10 | J6: 10

Sheet Calcs
A1: Per-use-case calculations (all formulas - do not edit)
A3: Use case | B3: Model | C3: PayGO dep | D3: PTU dep | E3: In tok/req | F3: Out tok/req | G3: Cache | H3: RPM P1 | I3: RPM P2 | J3: RPM P3 | K3: TPM/PTU | L3: Out ratio | M3: Eff in $/1M | N3: Eff cached $/1M | O3: Eff out $/1M | P3: In TPM P1 | Q3: In TPM P2 | R3: In TPM P3 | S3: Out TPM P1 | T3: Out TPM P2 | U3: Out TPM P3 | V3: Norm TPM P1 | W3: Norm TPM P2 | X3: Norm TPM P3 | Y3: Cost P1 $ | Z3: Cost P2 $ | AA3: Cost P3 $ | AB3: PayGO $/mo | AC3: In tok/mo | AD3: Out tok/mo | AE3: Peak RPM | AF3: Peak total TPM | AG3: Peak norm TPM | AH3: Exact PTUs (solo) | AI3: PTUs solo deploy
A4: =IF(UseCases!A4="","",UseCases!A4) -> RAG Chat | B4: =IF($A4="","",UseCases!B4) -> gpt-5 | C4: =IF($A4="","",UseCases!C4) -> Global | D4: =IF($A4="","",UseCases!D4) -> Global | E4: =IF($A4="","",UseCases!E4) -> 3500 | F4: =IF($A4="","",UseCases!F4) -> 300 | G4: =IF($A4="","",UseCases!G4) -> 0.3 | H4: =IF($A4="","",N(UseCases!H4)) -> 75 | I4: =IF($A4="","",N(UseCases!I4)) -> 10 | J4: =IF($A4="","",N(UseCases!J4)) -> 10 | K4: =IF($A4="","",INDEX(Catalog!$B$4:$B$23,MATCH($B4,Catalog!$A$4:$A$23,0))) -> 4750 | L4: =IF($A4="","",INDEX(Catalog!$C$4:$C$23,MATCH($B4,Catalog!$A$4:$A$23,0))) -> 8 | M4: =IF($A4="","",INDEX(Catalog!$H$4:$H$23,MATCH($B4,Catalog!$A$4:$A$23,0))*INDEX(Catalog!$B$35:$B$37,MATCH($C4,Catalog!$A$35:$A$37,0))) -> 1.25 | N4: =IF($A4="","",INDEX(Catalog!$I$4:$I$23,MATCH($B4,Catalog!$A$4:$A$23,0))*INDEX(Catalog!$B$35:$B$37,MATCH($C4,Catalog!$A$35:$A$37,0))) -> 0.125 | O4: =IF($A4="","",INDEX(Catalog!$J$4:$J$23,MATCH($B4,Catalog!$A$4:$A$23,0))*INDEX(Catalog!$B$35:$B$37,MATCH($C4,Catalog!$A$35:$A$37,0))) -> 10 | P4: =IF($A4="","",H4*$E4) -> 262500 | Q4: =IF($A4="","",I4*$E4) -> 35000 | R4: =IF($A4="","",J4*$E4) -> 35000 | S4: =IF($A4="","",H4*$F4) -> 22500 | T4: =IF($A4="","",I4*$F4) -> 3000 | U4: =IF($A4="","",J4*$F4) -> 3000 | V4: =IF($A4="","",P4*(1-$G4)+S4*$L4) -> 363750 | W4: =IF($A4="","",Q4*(1-$G4)+T4*$L4) -> 48500 | X4: =IF($A4="","",R4*(1-$G4)+U4*$L4) -> 48500 | Y4: =IF($A4="","",(P4*60*LoadPeriods!$E$4*((1-$G4)*$M4+$G4*$N4)+S4*60*LoadPeriods!$E$4*$O4)/1000000) -> 6059.6443 | Z4: =IF($A4="","",(Q4*60*LoadPeriods!$E$5*((1-$G4)*$M4+$G4*$N4)+T4*60*LoadPeriods!$E$5*$O4)/1000000) -> 1131.1336 | AA4: =IF($A4="","",(R4*60*LoadPeriods!$E$6*((1-$G4)*$M4+$G4*$N4)+U4*60*LoadPeriods!$E$6*$O4)/1000000) -> 775.63446 | AB4: =IF($A4="","",SUM(Y4:AA4)) -> 7966.4123 | AC4: =IF($A4="","",SUMPRODUCT(P4:R4,60*TRANSPOSE(LoadPeriods!$E$4:$E$6))) -> 4501706250 | AD4: =IF($A4="","",SUMPRODUCT(S4:U4,60*TRANSPOSE(LoadPeriods!$E$4:$E$6))) -> 3.8586054e+08 | AE4: =IF($A4="","",MAX(H4:J4)) -> 75 | AF4: =IF($A4="","",MAX(P4+S4,Q4+T4,R4+U4)) -> 285000 | AG4: =IF($A4="","",MAX(V4:X4)) -> 363750 | AH4: =IF($A4="","",AG4/K4) -> 76.578947 | AI4: =IF($A4="","",IF(AH4=0,0,IF(AH4<=IF($D4="Regional",INDEX(Catalog!$F$4:$F$23,MATCH($B4,Catalog!$A$4:$A$23,0)),INDEX(Catalog!$D$4:$D$23,MATCH($B4,Catalog!$A$4:$A$23,0))),IF($D4="Regional",INDEX(Catalog!$F$4:$F$23,MATCH($B4,Catalog!$A$4:$A$23,0)),INDEX(Catalog!$D$4:$D$23,MATCH($B4,Catalog!$A$4:$A$23,0))),IF($D4="Regional",INDEX(Catalog!$F$4:$F$23,MATCH($B4,Catalog!$A$4:$A$23,0)),INDEX(Catalog!$D$4:$D$23,MATCH($B4,Catalog!$A$4:$A$23,0)))+CEILING(AH4-IF($D4="Regional",INDEX(Catalog!$F$4:$F$23,MATCH($B4,Catalog!$A$4:$A$23,0)),INDEX(Catalog!$D$4:$D$23,MATCH($B4,Catalog!$A$4:$A$23,0))),IF($D4="Regional",INDEX(Catalog!$G$4:$G$23,MATCH($B4,Catalog!$A$4:$A$23,0)),INDEX(Catalog!$E$4:$E$23,MATCH($B4,Catalog!$A$4:$A$23,0))))))) -> 80
A5: =IF(UseCases!A5="","",UseCases!A5) -> Summarization | B5: =IF($A5="","",UseCases!B5) -> gpt-5 | C5: =IF($A5="","",UseCases!C5) -> Global | D5: =IF($A5="","",UseCases!D5) -> Global | E5: =IF($A5="","",UseCases!E5) -> 5000 | F5: =IF($A5="","",UseCases!F5) -> 300 | G5: =IF($A5="","",UseCases!G5) -> 0.1 | H5: =IF($A5="","",N(UseCases!H5)) -> 75 | I5: =IF($A5="","",N(UseCases!I5)) -> 10 | J5: =IF($A5="","",N(UseCases!J5)) -> 10 | K5: =IF($A5="","",INDEX(Catalog!$B$4:$B$23,MATCH($B5,Catalog!$A$4:$A$23,0))) -> 4750 | L5: =IF($A5="","",INDEX(Catalog!$C$4:$C$23,MATCH($B5,Catalog!$A$4:$A$23,0))) -> 8 | M5: =IF($A5="","",INDEX(Catalog!$H$4:$H$23,MATCH($B5,Catalog!$A$4:$A$23,0))*INDEX(Catalog!$B$35:$B$37,MATCH($C5,Catalog!$A$35:$A$37,0))) -> 1.25 | N5: =IF($A5="","",INDEX(Catalog!$I$4:$I$23,MATCH($B5,Catalog!$A$4:$A$23,0))*INDEX(Catalog!$B$35:$B$37,MATCH($C5,Catalog!$A$35:$A$37,0))) -> 0.125 | O5: =IF($A5="","",INDEX(Catalog!$J$4:$J$23,MATCH($B5,Catalog!$A$4:$A$23,0))*INDEX(Catalog!$B$35:$B$37,MATCH($C5,Catalog!$A$35:$A$37,0))) -> 10 | P5: =IF($A5="","",H5*$E5) -> 375000 | Q5: =IF($A5="","",I5*$E5) -> 50000 | R5: =IF($A5="","",J5*$E5) -> 50000 | S5: =IF($A5="","",H5*$F5) -> 22500 | T5: =IF($A5="","",I5*$F5) -> 3000 | U5: =IF($A5="","",J5*$F5) -> 3000 | V5: =IF($A5="","",P5*(1-$G5)+S5*$L5) -> 517500 | W5: =IF($A5="","",Q5*(1-$G5)+T5*$L5) -> 69000 | X5: =IF($A5="","",R5*(1-$G5)+U5*$L5) -> 69000 | Y5: =IF($A5="","",(P5*60*LoadPeriods!$E$4*((1-$G5)*$M5+$G5*$N5)+S5*60*LoadPeriods!$E$4*$O5)/1000000) -> 8499.4001 | Z5: =IF($A5="","",(Q5*60*LoadPeriods!$E$5*((1-$G5)*$M5+$G5*$N5)+T5*60*LoadPeriods!$E$5*$O5)/1000000) -> 1586.5547 | AA5: =IF($A5="","",(R5*60*LoadPeriods!$E$6*((1-$G5)*$M5+$G5*$N5)+U5*60*LoadPeriods!$E$6*$O5)/1000000) -> 1087.9232 | AB5: =IF($A5="","",SUM(Y5:AA5)) -> 11173.878 | AC5: =IF($A5="","",SUMPRODUCT(P5:R5,60*TRANSPOSE(LoadPeriods!$E$4:$E$6))) -> 6.4310089e+09 | AD5: =IF($A5="","",SUMPRODUCT(S5:U5,60*TRANSPOSE(LoadPeriods!$E$4:$E$6))) -> 3.8586054e+08 | AE5: =IF($A5="","",MAX(H5:J5)) -> 75 | AF5: =IF($A5="","",MAX(P5+S5,Q5+T5,R5+U5)) -> 397500 | AG5: =IF($A5="","",MAX(V5:X5)) -> 517500 | AH5: =IF($A5="","",AG5/K5) -> 108.94737 | AI5: =IF($A5="","",IF(AH5=0,0,IF(AH5<=IF($D5="Regional",INDEX(Catalog!$F$4:$F$23,MATCH($B5,Catalog!$A$4:$A$23,0)),INDEX(Catalog!$D$4:$D$23,MATCH($B5,Catalog!$A$4:$A$23,0))),IF($D5="Regional",INDEX(Catalog!$F$4:$F$23,MATCH($B5,Catalog!$A$4:$A$23,0)),INDEX(Catalog!$D$4:$D$23,MATCH($B5,Catalog!$A$4:$A$23,0))),IF($D5="Regional",INDEX(Catalog!$F$4:$F$23,MATCH($B5,Catalog!$A$4:$A$23,0)),INDEX(Catalog!$D$4:$D$23,MATCH($B5,Catalog!$A$4:$A$23,0)))+CEILING(AH5-IF($D5="Regional",INDEX(Catalog!$F$4:$F$23,MATCH($B5,Catalog!$A$4:$A$23,0)),INDEX(Catalog!$D$4:$D$23,MATCH($B5,Catalog!$A$4:$A$23,0))),IF($D5="Regional",INDEX(Catalog!$G$4:$G$23,MATCH($B5,Catalog!$A$4:$A$23,0)),INDEX(Catalog!$E$4:$E$23,MATCH($B5,Catalog!$A$4:$A$23,0))))))) -> 110
A6: =IF(UseCases!A6="","",UseCases!A6) -> Classification | B6: =IF($A6="","",UseCases!B6) -> gpt-5-mini | C6: =IF($A6="","",UseCases!C6) -> Global | D6: =IF($A6="","",UseCases!D6) -> Global | E6: =IF($A6="","",UseCases!E6) -> 3800 | F6: =IF($A6="","",UseCases!F6) -> 10 | G6: =IF($A6="","",UseCases!G6) -> 0.5 | H6: =IF($A6="","",N(UseCases!H6)) -> 75 | I6: =IF($A6="","",N(UseCases!I6)) -> 10 | J6: =IF($A6="","",N(UseCases!J6)) -> 10 | K6: =IF($A6="","",INDEX(Catalog!$B$4:$B$23,MATCH($B6,Catalog!$A$4:$A$23,0))) -> 23750 | L6: =IF($A6="","",INDEX(Catalog!$C$4:$C$23,MATCH($B6,Catalog!$A$4:$A$23,0))) -> 8 | M6: =IF($A6="","",INDEX(Catalog!$H$4:$H$23,MATCH($B6,Catalog!$A$4:$A$23,0))*INDEX(Catalog!$B$35:$B$37,MATCH($C6,Catalog!$A$35:$A$37,0))) -> 0.25 | N6: =IF($A6="","",INDEX(Catalog!$I$4:$I$23,MATCH($B6,Catalog!$A$4:$A$23,0))*INDEX(Catalog!$B$35:$B$37,MATCH($C6,Catalog!$A$35:$A$37,0))) -> 0.025 | O6: =IF($A6="","",INDEX(Catalog!$J$4:$J$23,MATCH($B6,Catalog!$A$4:$A$23,0))*INDEX(Catalog!$B$35:$B$37,MATCH($C6,Catalog!$A$35:$A$37,0))) -> 2 | P6: =IF($A6="","",H6*$E6) -> 285000 | Q6: =IF($A6="","",I6*$E6) -> 38000 | R6: =IF($A6="","",J6*$E6) -> 38000 | S6: =IF($A6="","",H6*$F6) -> 750 | T6: =IF($A6="","",I6*$F6) -> 100 | U6: =IF($A6="","",J6*$F6) -> 100 | V6: =IF($A6="","",P6*(1-$G6)+S6*$L6) -> 148500 | W6: =IF($A6="","",Q6*(1-$G6)+T6*$L6) -> 19800 | X6: =IF($A6="","",R6*(1-$G6)+U6*$L6) -> 19800 | Y6: =IF($A6="","",(P6*60*LoadPeriods!$E$4*((1-$G6)*$M6+$G6*$N6)+S6*60*LoadPeriods!$E$4*$O6)/1000000) -> 530.75391 | Z6: =IF($A6="","",(Q6*60*LoadPeriods!$E$5*((1-$G6)*$M6+$G6*$N6)+T6*60*LoadPeriods!$E$5*$O6)/1000000) -> 99.074062 | AA6: =IF($A6="","",(R6*60*LoadPeriods!$E$6*((1-$G6)*$M6+$G6*$N6)+U6*60*LoadPeriods!$E$6*$O6)/1000000) -> 67.9365 | AB6: =IF($A6="","",SUM(Y6:AA6)) -> 697.76447 | AC6: =IF($A6="","",SUMPRODUCT(P6:R6,60*TRANSPOSE(LoadPeriods!$E$4:$E$6))) -> 4.8875668e+09 | AD6: =IF($A6="","",SUMPRODUCT(S6:U6,60*TRANSPOSE(LoadPeriods!$E$4:$E$6))) -> 12862018 | AE6: =IF($A6="","",MAX(H6:J6)) -> 75 | AF6: =IF($A6="","",MAX(P6+S6,Q6+T6,R6+U6)) -> 285750 | AG6: =IF($A6="","",MAX(V6:X6)) -> 148500 | AH6: =IF($A6="","",AG6/K6) -> 6.2526316 | AI6: =IF($A6="","",IF(AH6=0,0,IF(AH6<=IF($D6="Regional",INDEX(Catalog!$F$4:$F$23,MATCH($B6,Catalog!$A$4:$A$23,0)),INDEX(Catalog!$D$4:$D$23,MATCH($B6,Catalog!$A$4:$A$23,0))),IF($D6="Regional",INDEX(Catalog!$F$4:$F$23,MATCH($B6,Catalog!$A$4:$A$23,0)),INDEX(Catalog!$D$4:$D$23,MATCH($B6,Catalog!$A$4:$A$23,0))),IF($D6="Regional",INDEX(Catalog!$F$4:$F$23,MATCH($B6,Catalog!$A$4:$A$23,0)),INDEX(Catalog!$D$4:$D$23,MATCH($B6,Catalog!$A$4:$A$23,0)))+CEILING(AH6-IF($D6="Regional",INDEX(Catalog!$F$4:$F$23,MATCH($B6,Catalog!$A$4:$A$23,0)),INDEX(Catalog!$D$4:$D$23,MATCH($B6,Catalog!$A$4:$A$23,0))),IF($D6="Regional",INDEX(Catalog!$G$4:$G$23,MATCH($B6,Catalog!$A$4:$A$23,0)),INDEX(Catalog!$E$4:$E$23,MATCH($B6,Catalog!$A$4:$A$23,0))))))) -> 15
A7: =IF(UseCases!A7="","",UseCases!A7) | B7: =IF($A7="","",UseCases!B7) | C7: =IF($A7="","",UseCases!C7) | D7: =IF($A7="","",UseCases!D7) | E7: =IF($A7="","",UseCases!E7) | F7: =IF($A7="","",UseCases!F7) | G7: =IF($A7="","",UseCases!G7) | H7: =IF($A7="","",N(UseCases!H7)) | I7: =IF($A7="","",N(UseCases!I7)) | J7: =IF($A7="","",N(UseCases!J7)) | K7: =IF($A7="","",INDEX(Catalog!$B$4:$B$23,MATCH($B7,Catalog!$A$4:$A$23,0))) | L7: =IF($A7="","",INDEX(Catalog!$C$4:$C$23,MATCH($B7,Catalog!$A$4:$A$23,0))) | M7: =IF($A7="","",INDEX(Catalog!$H$4:$H$23,MATCH($B7,Catalog!$A$4:$A$23,0))*INDEX(Catalog!$B$35:$B$37,MATCH($C7,Catalog!$A$35:$A$37,0))) | N7: =IF($A7="","",INDEX(Catalog!$I$4:$I$23,MATCH($B7,Catalog!$A$4:$A$23,0))*INDEX(Catalog!$B$35:$B$37,MATCH($C7,Catalog!$A$35:$A$37,0))) | O7: =IF($A7="","",INDEX(Catalog!$J$4:$J$23,MATCH($B7,Catalog!$A$4:$A$23,0))*INDEX(Catalog!$B$35:$B$37,MATCH($C7,Catalog!$A$35:$A$37,0))) | P7: =IF($A7="","",H7*$E7) | Q7: =IF($A7="","",I7*$E7) | R7: =IF($A7="","",J7*$E7) | S7: =IF($A7="","",H7*$F7) | T7: =IF($A7="","",I7*$F7) | U7: =IF($A7="","",J7*$F7) | V7: =IF($A7="","",P7*(1-$G7)+S7*$L7) | W7: =IF($A7="","",Q7*(1-$G7)+T7*$L7) | X7: =IF($A7="","",R7*(1-$G7)+U7*$L7) | Y7: =IF($A7="","",(P7*60*LoadPeriods!$E$4*((1-$G7)*$M7+$G7*$N7)+S7*60*LoadPeriods!$E$4*$O7)/1000000) | Z7: =IF($A7="","",(Q7*60*LoadPeriods!$E$5*((1-$G7)*$M7+$G7*$N7)+T7*60*LoadPeriods!$E$5*$O7)/1000000) | AA7: =IF($A7="","",(R7*60*LoadPeriods!$E$6*((1-$G7)*$M7+$G7*$N7)+U7*60*LoadPeriods!$E$6*$O7)/1000000) | AB7: =IF($A7="","",SUM(Y7:AA7)) | AC7: =IF($A7="","",SUMPRODUCT(P7:R7,60*TRANSPOSE(LoadPeriods!$E$4:$E$6))) | AD7: =IF($A7="","",SUMPRODUCT(S7:U7,60*TRANSPOSE(LoadPeriods!$E$4:$E$6))) | AE7: =IF($A7="","",MAX(H7:J7)) | AF7: =IF($A7="","",MAX(P7+S7,Q7+T7,R7+U7)) | AG7: =IF($A7="","",MAX(V7:X7)) | AH7: =IF($A7="","",AG7/K7) | AI7: =IF($A7="","",IF(AH7=0,0,IF(AH7<=IF($D7="Regional",INDEX(Catalog!$F$4:$F$23,MATCH($B7,Catalog!$A$4:$A$23,0)),INDEX(Catalog!$D$4:$D$23,MATCH($B7,Catalog!$A$4:$A$23,0))),IF($D7="Regional",INDEX(Catalog!$F$4:$F$23,MATCH($B7,Catalog!$A$4:$A$23,0)),INDEX(Catalog!$D$4:$D$23,MATCH($B7,Catalog!$A$4:$A$23,0))),IF($D7="Regional",INDEX(Catalog!$F$4:$F$23,MATCH($B7,Catalog!$A$4:$A$23,0)),INDEX(Catalog!$D$4:$D$23,MATCH($B7,Catalog!$A$4:$A$23,0)))+CEILING(AH7-IF($D7="Regional",INDEX(Catalog!$F$4:$F$23,MATCH($B7,Catalog!$A$4:$A$23,0)),INDEX(Catalog!$D$4:$D$23,MATCH($B7,Catalog!$A$4:$A$23,0))),IF($D7="Regional",INDEX(Catalog!$G$4:$G$23,MATCH($B7,Catalog!$A$4:$A$23,0)),INDEX(Catalog!$E$4:$E$23,MATCH($B7,Catalog!$A$4:$A$23,0)))))))
A8: =IF(UseCases!A8="","",UseCases!A8) | B8: =IF($A8="","",UseCases!B8) | C8: =IF($A8="","",UseCases!C8) | D8: =IF($A8="","",UseCases!D8) | E8: =IF($A8="","",UseCases!E8) | F8: =IF($A8="","",UseCases!F8) | G8: =IF($A8="","",UseCases!G8) | H8: =IF($A8="","",N(UseCases!H8)) | I8: =IF($A8="","",N(UseCases!I8)) | J8: =IF($A8="","",N(UseCases!J8)) | K8: =IF($A8="","",INDEX(Catalog!$B$4:$B$23,MATCH($B8,Catalog!$A$4:$A$23,0))) | L8: =IF($A8="","",INDEX(Catalog!$C$4:$C$23,MATCH($B8,Catalog!$A$4:$A$23,0))) | M8: =IF($A8="","",INDEX(Catalog!$H$4:$H$23,MATCH($B8,Catalog!$A$4:$A$23,0))*INDEX(Catalog!$B$35:$B$37,MATCH($C8,Catalog!$A$35:$A$37,0))) | N8: =IF($A8="","",INDEX(Catalog!$I$4:$I$23,MATCH($B8,Catalog!$A$4:$A$23,0))*INDEX(Catalog!$B$35:$B$37,MATCH($C8,Catalog!$A$35:$A$37,0))) | O8: =IF($A8="","",INDEX(Catalog!$J$4:$J$23,MATCH($B8,Catalog!$A$4:$A$23,0))*INDEX(Catalog!$B$35:$B$37,MATCH($C8,Catalog!$A$35:$A$37,0))) | P8: =IF($A8="","",H8*$E8) | Q8: =IF($A8="","",I8*$E8) | R8: =IF($A8="","",J8*$E8) | S8: =IF($A8="","",H8*$F8) | T8: =IF($A8="","",I8*$F8) | U8: =IF($A8="","",J8*$F8) | V8: =IF($A8="","",P8*(1-$G8)+S8*$L8) | W8: =IF($A8="","",Q8*(1-$G8)+T8*$L8) | X8: =IF($A8="","",R8*(1-$G8)+U8*$L8) | Y8: =IF($A8="","",(P8*60*LoadPeriods!$E$4*((1-$G8)*$M8+$G8*$N8)+S8*60*LoadPeriods!$E$4*$O8)/1000000) | Z8: =IF($A8="","",(Q8*60*LoadPeriods!$E$5*((1-$G8)*$M8+$G8*$N8)+T8*60*LoadPeriods!$E$5*$O8)/1000000) | AA8: =IF($A8="","",(R8*60*LoadPeriods!$E$6*((1-$G8)*$M8+$G8*$N8)+U8*60*LoadPeriods!$E$6*$O8)/1000000) | AB8: =IF($A8="","",SUM(Y8:AA8)) | AC8: =IF($A8="","",SUMPRODUCT(P8:R8,60*TRANSPOSE(LoadPeriods!$E$4:$E$6))) | AD8: =IF($A8="","",SUMPRODUCT(S8:U8,60*TRANSPOSE(LoadPeriods!$E$4:$E$6))) | AE8: =IF($A8="","",MAX(H8:J8)) | AF8: =IF($A8="","",MAX(P8+S8,Q8+T8,R8+U8)) | AG8: =IF($A8="","",MAX(V8:X8)) | AH8: =IF($A8="","",AG8/K8) | AI8: =IF($A8="","",IF(AH8=0,0,IF(AH8<=IF($D8="Regional",INDEX(Catalog!$F$4:$F$23,MATCH($B8,Catalog!$A$4:$A$23,0)),INDEX(Catalog!$D$4:$D$23,MATCH($B8,Catalog!$A$4:$A$23,0))),IF($D8="Regional",INDEX(Catalog!$F$4:$F$23,MATCH($B8,Catalog!$A$4:$A$23,0)),INDEX(Catalog!$D$4:$D$23,MATCH($B8,Catalog!$A$4:$A$23,0))),IF($D8="Regional",INDEX(Catalog!$F$4:$F$23,MATCH($B8,Catalog!$A$4:$A$23,0)),INDEX(Catalog!$D$4:$D$23,MATCH($B8,Catalog!$A$4:$A$23,0)))+CEILING(AH8-IF($D8="Regional",INDEX(Catalog!$F$4:$F$23,MATCH($B8,Catalog!$A$4:$A$23,0)),INDEX(Catalog!$D$4:$D$23,MATCH($B8,Catalog!$A$4:$A$23,0))),IF($D8="Regional",INDEX(Catalog!$G$4:$G$23,MATCH($B8,Catalog!$A$4:$A$23,0)),INDEX(Catalog!$E$4:$E$23,MATCH($B8,Catalog!$A$4:$A$23,0)))))))
A9: =IF(UseCases!A9="","",UseCases!A9) | B9: =IF($A9="","",UseCases!B9) | C9: =IF($A9="","",UseCases!C9) | D9: =IF($A9="","",UseCases!D9) | E9: =IF($A9="","",UseCases!E9) | F9: =IF($A9="","",UseCases!F9) | G9: =IF($A9="","",UseCases!G9) | H9: =IF($A9="","",N(UseCases!H9)) | I9: =IF($A9="","",N(UseCases!I9)) | J9: =IF($A9="","",N(UseCases!J9)) | K9: =IF($A9="","",INDEX(Catalog!$B$4:$B$23,MATCH($B9,Catalog!$A$4:$A$23,0))) | L9: =IF($A9="","",INDEX(Catalog!$C$4:$C$23,MATCH($B9,Catalog!$A$4:$A$23,0))) | M9: =IF($A9="","",INDEX(Catalog!$H$4:$H$23,MATCH($B9,Catalog!$A$4:$A$23,0))*INDEX(Catalog!$B$35:$B$37,MATCH($C9,Catalog!$A$35:$A$37,0))) | N9: =IF($A9="","",INDEX(Catalog!$I$4:$I$23,MATCH($B9,Catalog!$A$4:$A$23,0))*INDEX(Catalog!$B$35:$B$37,MATCH($C9,Catalog!$A$35:$A$37,0))) | O9: =IF($A9="","",INDEX(Catalog!$J$4:$J$23,MATCH($B9,Catalog!$A$4:$A$23,0))*INDEX(Catalog!$B$35:$B$37,MATCH($C9,Catalog!$A$35:$A$37,0))) | P9: =IF($A9="","",H9*$E9) | Q9: =IF($A9="","",I9*$E9) | R9: =IF($A9="","",J9*$E9) | S9: =IF($A9="","",H9*$F9) | T9: =IF($A9="","",I9*$F9) | U9: =IF($A9="","",J9*$F9) | V9: =IF($A9="","",P9*(1-$G9)+S9*$L9) | W9: =IF($A9="","",Q9*(1-$G9)+T9*$L9) | X9: =IF($A9="","",R9*(1-$G9)+U9*$L9) | Y9: =IF($A9="","",(P9*60*LoadPeriods!$E$4*((1-$G9)*$M9+$G9*$N9)+S9*60*LoadPeriods!$E$4*$O9)/1000000) | Z9: =IF($A9="","",(Q9*60*LoadPeriods!$E$5*((1-$G9)*$M9+$G9*$N9)+T9*60*LoadPeriods!$E$5*$O9)/1000000) | AA9: =IF($A9="","",(R9*60*LoadPeriods!$E$6*((1-$G9)*$M9+$G9*$N9)+U9*60*LoadPeriods!$E$6*$O9)/1000000) | AB9: =IF($A9="","",SUM(Y9:AA9)) | AC9: =IF($A9="","",SUMPRODUCT(P9:R9,60*TRANSPOSE(LoadPeriods!$E$4:$E$6))) | AD9: =IF($A9="","",SUMPRODUCT(S9:U9,60*TRANSPOSE(LoadPeriods!$E$4:$E$6))) | AE9: =IF($A9="","",MAX(H9:J9)) | AF9: =IF($A9="","",MAX(P9+S9,Q9+T9,R9+U9)) | AG9: =IF($A9="","",MAX(V9:X9)) | AH9: =IF($A9="","",AG9/K9) | AI9: =IF($A9="","",IF(AH9=0,0,IF(AH9<=IF($D9="Regional",INDEX(Catalog!$F$4:$F$23,MATCH($B9,Catalog!$A$4:$A$23,0)),INDEX(Catalog!$D$4:$D$23,MATCH($B9,Catalog!$A$4:$A$23,0))),IF($D9="Regional",INDEX(Catalog!$F$4:$F$23,MATCH($B9,Catalog!$A$4:$A$23,0)),INDEX(Catalog!$D$4:$D$23,MATCH($B9,Catalog!$A$4:$A$23,0))),IF($D9="Regional",INDEX(Catalog!$F$4:$F$23,MATCH($B9,Catalog!$A$4:$A$23,0)),INDEX(Catalog!$D$4:$D$23,MATCH($B9,Catalog!$A$4:$A$23,0)))+CEILING(AH9-IF($D9="Regional",INDEX(Catalog!$F$4:$F$23,MATCH($B9,Catalog!$A$4:$A$23,0)),INDEX(Catalog!$D$4:$D$23,MATCH($B9,Catalog!$A$4:$A$23,0))),IF($D9="Regional",INDEX(Catalog!$G$4:$G$23,MATCH($B9,Catalog!$A$4:$A$23,0)),INDEX(Catalog!$E$4:$E$23,MATCH($B9,Catalog!$A$4:$A$23,0)))))))
A10: =IF(UseCases!A10="","",UseCases!A10) | B10: =IF($A10="","",UseCases!B10) | C10: =IF($A10="","",UseCases!C10) | D10: =IF($A10="","",UseCases!D10) | E10: =IF($A10="","",UseCases!E10) | F10: =IF($A10="","",UseCases!F10) | G10: =IF($A10="","",UseCases!G10) | H10: =IF($A10="","",N(UseCases!H10)) | I10: =IF($A10="","",N(UseCases!I10)) | J10: =IF($A10="","",N(UseCases!J10)) | K10: =IF($A10="","",INDEX(Catalog!$B$4:$B$23,MATCH($B10,Catalog!$A$4:$A$23,0))) | L10: =IF($A10="","",INDEX(Catalog!$C$4:$C$23,MATCH($B10,Catalog!$A$4:$A$23,0))) | M10: =IF($A10="","",INDEX(Catalog!$H$4:$H$23,MATCH($B10,Catalog!$A$4:$A$23,0))*INDEX(Catalog!$B$35:$B$37,MATCH($C10,Catalog!$A$35:$A$37,0))) | N10: =IF($A10="","",INDEX(Catalog!$I$4:$I$23,MATCH($B10,Catalog!$A$4:$A$23,0))*INDEX(Catalog!$B$35:$B$37,MATCH($C10,Catalog!$A$35:$A$37,0))) | O10: =IF($A10="","",INDEX(Catalog!$J$4:$J$23,MATCH($B10,Catalog!$A$4:$A$23,0))*INDEX(Catalog!$B$35:$B$37,MATCH($C10,Catalog!$A$35:$A$37,0))) | P10: =IF($A10="","",H10*$E10) | Q10: =IF($A10="","",I10*$E10) | R10: =IF($A10="","",J10*$E10) | S10: =IF($A10="","",H10*$F10) | T10: =IF($A10="","",I10*$F10) | U10: =IF($A10="","",J10*$F10) | V10: =IF($A10="","",P10*(1-$G10)+S10*$L10) | W10: =IF($A10="","",Q10*(1-$G10)+T10*$L10) | X10: =IF($A10="","",R10*(1-$G10)+U10*$L10) | Y10: =IF($A10="","",(P10*60*LoadPeriods!$E$4*((1-$G10)*$M10+$G10*$N10)+S10*60*LoadPeriods!$E$4*$O10)/1000000) | Z10: =IF($A10="","",(Q10*60*LoadPeriods!$E$5*((1-$G10)*$M10+$G10*$N10)+T10*60*LoadPeriods!$E$5*$O10)/1000000) | AA10: =IF($A10="","",(R10*60*LoadPeriods!$E$6*((1-$G10)*$M10+$G10*$N10)+U10*60*LoadPeriods!$E$6*$O10)/1000000) | AB10: =IF($A10="","",SUM(Y10:AA10)) | AC10: =IF($A10="","",SUMPRODUCT(P10:R10,60*TRANSPOSE(LoadPeriods!$E$4:$E$6))) | AD10: =IF($A10="","",SUMPRODUCT(S10:U10,60*TRANSPOSE(LoadPeriods!$E$4:$E$6))) | AE10: =IF($A10="","",MAX(H10:J10)) | AF10: =IF($A10="","",MAX(P10+S10,Q10+T10,R10+U10)) | AG10: =IF($A10="","",MAX(V10:X10)) | AH10: =IF($A10="","",AG10/K10) | AI10: =IF($A10="","",IF(AH10=0,0,IF(AH10<=IF($D10="Regional",INDEX(Catalog!$F$4:$F$23,MATCH($B10,Catalog!$A$4:$A$23,0)),INDEX(Catalog!$D$4:$D$23,MATCH($B10,Catalog!$A$4:$A$23,0))),IF($D10="Regional",INDEX(Catalog!$F$4:$F$23,MATCH($B10,Catalog!$A$4:$A$23,0)),INDEX(Catalog!$D$4:$D$23,MATCH($B10,Catalog!$A$4:$A$23,0))),IF($D10="Regional",INDEX(Catalog!$F$4:$F$23,MATCH($B10,Catalog!$A$4:$A$23,0)),INDEX(Catalog!$D$4:$D$23,MATCH($B10,Catalog!$A$4:$A$23,0)))+CEILING(AH10-IF($D10="Regional",INDEX(Catalog!$F$4:$F$23,MATCH($B10,Catalog!$A$4:$A$23,0)),INDEX(Catalog!$D$4:$D$23,MATCH($B10,Catalog!$A$4:$A$23,0))),IF($D10="Regional",INDEX(Catalog!$G$4:$G$23,MATCH($B10,Catalog!$A$4:$A$23,0)),INDEX(Catalog!$E$4:$E$23,MATCH($B10,Catalog!$A$4:$A$23,0)))))))
A11: =IF(UseCases!A11="","",UseCases!A11) | B11: =IF($A11="","",UseCases!B11) | C11: =IF($A11="","",UseCases!C11) | D11: =IF($A11="","",UseCases!D11) | E11: =IF($A11="","",UseCases!E11) | F11: =IF($A11="","",UseCases!F11) | G11: =IF($A11="","",UseCases!G11) | H11: =IF($A11="","",N(UseCases!H11)) | I11: =IF($A11="","",N(UseCases!I11)) | J11: =IF($A11="","",N(UseCases!J11)) | K11: =IF($A11="","",INDEX(Catalog!$B$4:$B$23,MATCH($B11,Catalog!$A$4:$A$23,0))) | L11: =IF($A11="","",INDEX(Catalog!$C$4:$C$23,MATCH($B11,Catalog!$A$4:$A$23,0))) | M11: =IF($A11="","",INDEX(Catalog!$H$4:$H$23,MATCH($B11,Catalog!$A$4:$A$23,0))*INDEX(Catalog!$B$35:$B$37,MATCH($C11,Catalog!$A$35:$A$37,0))) | N11: =IF($A11="","",INDEX(Catalog!$I$4:$I$23,MATCH($B11,Catalog!$A$4:$A$23,0))*INDEX(Catalog!$B$35:$B$37,MATCH($C11,Catalog!$A$35:$A$37,0))) | O11: =IF($A11="","",INDEX(Catalog!$J$4:$J$23,MATCH($B11,Catalog!$A$4:$A$23,0))*INDEX(Catalog!$B$35:$B$37,MATCH($C11,Catalog!$A$35:$A$37,0))) | P11: =IF($A11="","",H11*$E11) | Q11: =IF($A11="","",I11*$E11) | R11: =IF($A11="","",J11*$E11) | S11: =IF($A11="","",H11*$F11) | T11: =IF($A11="","",I11*$F11) | U11: =IF($A11="","",J11*$F11) | V11: =IF($A11="","",P11*(1-$G11)+S11*$L11) | W11: =IF($A11="","",Q11*(1-$G11)+T11*$L11) | X11: =IF($A11="","",R11*(1-$G11)+U11*$L11) | Y11: =IF($A11="","",(P11*60*LoadPeriods!$E$4*((1-$G11)*$M11+$G11*$N11)+S11*60*LoadPeriods!$E$4*$O11)/1000000) | Z11: =IF($A11="","",(Q11*60*LoadPeriods!$E$5*((1-$G11)*$M11+$G11*$N11)+T11*60*LoadPeriods!$E$5*$O11)/1000000) | AA11: =IF($A11="","",(R11*60*LoadPeriods!$E$6*((1-$G11)*$M11+$G11*$N11)+U11*60*LoadPeriods!$E$6*$O11)/1000000) | AB11: =IF($A11="","",SUM(Y11:AA11)) | AC11: =IF($A11="","",SUMPRODUCT(P11:R11,60*TRANSPOSE(LoadPeriods!$E$4:$E$6))) | AD11: =IF($A11="","",SUMPRODUCT(S11:U11,60*TRANSPOSE(LoadPeriods!$E$4:$E$6))) | AE11: =IF($A11="","",MAX(H11:J11)) | AF11: =IF($A11="","",MAX(P11+S11,Q11+T11,R11+U11)) | AG11: =IF($A11="","",MAX(V11:X11)) | AH11: =IF($A11="","",AG11/K11) | AI11: =IF($A11="","",IF(AH11=0,0,IF(AH11<=IF($D11="Regional",INDEX(Catalog!$F$4:$F$23,MATCH($B11,Catalog!$A$4:$A$23,0)),INDEX(Catalog!$D$4:$D$23,MATCH($B11,Catalog!$A$4:$A$23,0))),IF($D11="Regional",INDEX(Catalog!$F$4:$F$23,MATCH($B11,Catalog!$A$4:$A$23,0)),INDEX(Catalog!$D$4:$D$23,MATCH($B11,Catalog!$A$4:$A$23,0))),IF($D11="Regional",INDEX(Catalog!$F$4:$F$23,MATCH($B11,Catalog!$A$4:$A$23,0)),INDEX(Catalog!$D$4:$D$23,MATCH($B11,Catalog!$A$4:$A$23,0)))+CEILING(AH11-IF($D11="Regional",INDEX(Catalog!$F$4:$F$23,MATCH($B11,Catalog!$A$4:$A$23,0)),INDEX(Catalog!$D$4:$D$23,MATCH($B11,Catalog!$A$4:$A$23,0))),IF($D11="Regional",INDEX(Catalog!$G$4:$G$23,MATCH($B11,Catalog!$A$4:$A$23,0)),INDEX(Catalog!$E$4:$E$23,MATCH($B11,Catalog!$A$4:$A$23,0)))))))
A12: =IF(UseCases!A12="","",UseCases!A12) | B12: =IF($A12="","",UseCases!B12) | C12: =IF($A12="","",UseCases!C12) | D12: =IF($A12="","",UseCases!D12) | E12: =IF($A12="","",UseCases!E12) | F12: =IF($A12="","",UseCases!F12) | G12: =IF($A12="","",UseCases!G12) | H12: =IF($A12="","",N(UseCases!H12)) | I12: =IF($A12="","",N(UseCases!I12)) | J12: =IF($A12="","",N(UseCases!J12)) | K12: =IF($A12="","",INDEX(Catalog!$B$4:$B$23,MATCH($B12,Catalog!$A$4:$A$23,0))) | L12: =IF($A12="","",INDEX(Catalog!$C$4:$C$23,MATCH($B12,Catalog!$A$4:$A$23,0))) | M12: =IF($A12="","",INDEX(Catalog!$H$4:$H$23,MATCH($B12,Catalog!$A$4:$A$23,0))*INDEX(Catalog!$B$35:$B$37,MATCH($C12,Catalog!$A$35:$A$37,0))) | N12: =IF($A12="","",INDEX(Catalog!$I$4:$I$23,MATCH($B12,Catalog!$A$4:$A$23,0))*INDEX(Catalog!$B$35:$B$37,MATCH($C12,Catalog!$A$35:$A$37,0))) | O12: =IF($A12="","",INDEX(Catalog!$J$4:$J$23,MATCH($B12,Catalog!$A$4:$A$23,0))*INDEX(Catalog!$B$35:$B$37,MATCH($C12,Catalog!$A$35:$A$37,0))) | P12: =IF($A12="","",H12*$E12) | Q12: =IF($A12="","",I12*$E12) | R12: =IF($A12="","",J12*$E12) | S12: =IF($A12="","",H12*$F12) | T12: =IF($A12="","",I12*$F12) | U12: =IF($A12="","",J12*$F12) | V12: =IF($A12="","",P12*(1-$G12)+S12*$L12) | W12: =IF($A12="","",Q12*(1-$G12)+T12*$L12) | X12: =IF($A12="","",R12*(1-$G12)+U12*$L12) | Y12: =IF($A12="","",(P12*60*LoadPeriods!$E$4*((1-$G12)*$M12+$G12*$N12)+S12*60*LoadPeriods!$E$4*$O12)/1000000) | Z12: =IF($A12="","",(Q12*60*LoadPeriods!$E$5*((1-$G12)*$M12+$G12*$N12)+T12*60*LoadPeriods!$E$5*$O12)/1000000) | AA12: =IF($A12="","",(R12*60*LoadPeriods!$E$6*((1-$G12)*$M12+$G12*$N12)+U12*60*LoadPeriods!$E$6*$O12)/1000000) | AB12: =IF($A12="","",SUM(Y12:AA12)) | AC12: =IF($A12="","",SUMPRODUCT(P12:R12,60*TRANSPOSE(LoadPeriods!$E$4:$E$6))) | AD12: =IF($A12="","",SUMPRODUCT(S12:U12,60*TRANSPOSE(LoadPeriods!$E$4:$E$6))) | AE12: =IF($A12="","",MAX(H12:J12)) | AF12: =IF($A12="","",MAX(P12+S12,Q12+T12,R12+U12)) | AG12: =IF($A12="","",MAX(V12:X12)) | AH12: =IF($A12="","",AG12/K12) | AI12: =IF($A12="","",IF(AH12=0,0,IF(AH12<=IF($D12="Regional",INDEX(Catalog!$F$4:$F$23,MATCH($B12,Catalog!$A$4:$A$23,0)),INDEX(Catalog!$D$4:$D$23,MATCH($B12,Catalog!$A$4:$A$23,0))),IF($D12="Regional",INDEX(Catalog!$F$4:$F$23,MATCH($B12,Catalog!$A$4:$A$23,0)),INDEX(Catalog!$D$4:$D$23,MATCH($B12,Catalog!$A$4:$A$23,0))),IF($D12="Regional",INDEX(Catalog!$F$4:$F$23,MATCH($B12,Catalog!$A$4:$A$23,0)),INDEX(Catalog!$D$4:$D$23,MATCH($B12,Catalog!$A$4:$A$23,0)))+CEILING(AH12-IF($D12="Regional",INDEX(Catalog!$F$4:$F$23,MATCH($B12,Catalog!$A$4:$A$23,0)),INDEX(Catalog!$D$4:$D$23,MATCH($B12,Catalog!$A$4:$A$23,0))),IF($D12="Regional",INDEX(Catalog!$G$4:$G$23,MATCH($B12,Catalog!$A$4:$A$23,0)),INDEX(Catalog!$E$4:$E$23,MATCH($B12,Catalog!$A$4:$A$23,0)))))))
A13: =IF(UseCases!A13="","",UseCases!A13) | B13: =IF($A13="","",UseCases!B13) | C13: =IF($A13="","",UseCases!C13) | D13: =IF($A13="","",UseCases!D13) | E13: =IF($A13="","",UseCases!E13) | F13: =IF($A13="","",UseCases!F13) | G13: =IF($A13="","",UseCases!G13) | H13: =IF($A13="","",N(UseCases!H13)) | I13: =IF($A13="","",N(UseCases!I13)) | J13: =IF($A13="","",N(UseCases!J13)) | K13: =IF($A13="","",INDEX(Catalog!$B$4:$B$23,MATCH($B13,Catalog!$A$4:$A$23,0))) | L13: =IF($A13="","",INDEX(Catalog!$C$4:$C$23,MATCH($B13,Catalog!$A$4:$A$23,0))) | M13: =IF($A13="","",INDEX(Catalog!$H$4:$H$23,MATCH($B13,Catalog!$A$4:$A$23,0))*INDEX(Catalog!$B$35:$B$37,MATCH($C13,Catalog!$A$35:$A$37,0))) | N13: =IF($A13="","",INDEX(Catalog!$I$4:$I$23,MATCH($B13,Catalog!$A$4:$A$23,0))*INDEX(Catalog!$B$35:$B$37,MATCH($C13,Catalog!$A$35:$A$37,0))) | O13: =IF($A13="","",INDEX(Catalog!$J$4:$J$23,MATCH($B13,Catalog!$A$4:$A$23,0))*INDEX(Catalog!$B$35:$B$37,MATCH($C13,Catalog!$A$35:$A$37,0))) | P13: =IF($A13="","",H13*$E13) | Q13: =IF($A13="","",I13*$E13) | R13: =IF($A13="","",J13*$E13) | S13: =IF($A13="","",H13*$F13) | T13: =IF($A13="","",I13*$F13) | U13: =IF($A13="","",J13*$F13) | V13: =IF($A13="","",P13*(1-$G13)+S13*$L13) | W13: =IF($A13="","",Q13*(1-$G13)+T13*$L13) | X13: =IF($A13="","",R13*(1-$G13)+U13*$L13) | Y13: =IF($A13="","",(P13*60*LoadPeriods!$E$4*((1-$G13)*$M13+$G13*$N13)+S13*60*LoadPeriods!$E$4*$O13)/1000000) | Z13: =IF($A13="","",(Q13*60*LoadPeriods!$E$5*((1-$G13)*$M13+$G13*$N13)+T13*60*LoadPeriods!$E$5*$O13)/1000000) | AA13: =IF($A13="","",(R13*60*LoadPeriods!$E$6*((1-$G13)*$M13+$G13*$N13)+U13*60*LoadPeriods!$E$6*$O13)/1000000) | AB13: =IF($A13="","",SUM(Y13:AA13)) | AC13: =IF($A13="","",SUMPRODUCT(P13:R13,60*TRANSPOSE(LoadPeriods!$E$4:$E$6))) | AD13: =IF($A13="","",SUMPRODUCT(S13:U13,60*TRANSPOSE(LoadPeriods!$E$4:$E$6))) | AE13: =IF($A13="","",MAX(H13:J13)) | AF13: =IF($A13="","",MAX(P13+S13,Q13+T13,R13+U13)) | AG13: =IF($A13="","",MAX(V13:X13)) | AH13: =IF($A13="","",AG13/K13) | AI13: =IF($A13="","",IF(AH13=0,0,IF(AH13<=IF($D13="Regional",INDEX(Catalog!$F$4:$F$23,MATCH($B13,Catalog!$A$4:$A$23,0)),INDEX(Catalog!$D$4:$D$23,MATCH($B13,Catalog!$A$4:$A$23,0))),IF($D13="Regional",INDEX(Catalog!$F$4:$F$23,MATCH($B13,Catalog!$A$4:$A$23,0)),INDEX(Catalog!$D$4:$D$23,MATCH($B13,Catalog!$A$4:$A$23,0))),IF($D13="Regional",INDEX(Catalog!$F$4:$F$23,MATCH($B13,Catalog!$A$4:$A$23,0)),INDEX(Catalog!$D$4:$D$23,MATCH($B13,Catalog!$A$4:$A$23,0)))+CEILING(AH13-IF($D13="Regional",INDEX(Catalog!$F$4:$F$23,MATCH($B13,Catalog!$A$4:$A$23,0)),INDEX(Catalog!$D$4:$D$23,MATCH($B13,Catalog!$A$4:$A$23,0))),IF($D13="Regional",INDEX(Catalog!$G$4:$G$23,MATCH($B13,Catalog!$A$4:$A$23,0)),INDEX(Catalog!$E$4:$E$23,MATCH($B13,Catalog!$A$4:$A$23,0)))))))
A14: =IF(UseCases!A14="","",UseCases!A14) | B14: =IF($A14="","",UseCases!B14) | C14: =IF($A14="","",UseCases!C14) | D14: =IF($A14="","",UseCases!D14) | E14: =IF($A14="","",UseCases!E14) | F14: =IF($A14="","",UseCases!F14) | G14: =IF($A14="","",UseCases!G14) | H14: =IF($A14="","",N(UseCases!H14)) | I14: =IF($A14="","",N(UseCases!I14)) | J14: =IF($A14="","",N(UseCases!J14)) | K14: =IF($A14="","",INDEX(Catalog!$B$4:$B$23,MATCH($B14,Catalog!$A$4:$A$23,0))) | L14: =IF($A14="","",INDEX(Catalog!$C$4:$C$23,MATCH($B14,Catalog!$A$4:$A$23,0))) | M14: =IF($A14="","",INDEX(Catalog!$H$4:$H$23,MATCH($B14,Catalog!$A$4:$A$23,0))*INDEX(Catalog!$B$35:$B$37,MATCH($C14,Catalog!$A$35:$A$37,0))) | N14: =IF($A14="","",INDEX(Catalog!$I$4:$I$23,MATCH($B14,Catalog!$A$4:$A$23,0))*INDEX(Catalog!$B$35:$B$37,MATCH($C14,Catalog!$A$35:$A$37,0))) | O14: =IF($A14="","",INDEX(Catalog!$J$4:$J$23,MATCH($B14,Catalog!$A$4:$A$23,0))*INDEX(Catalog!$B$35:$B$37,MATCH($C14,Catalog!$A$35:$A$37,0))) | P14: =IF($A14="","",H14*$E14) | Q14: =IF($A14="","",I14*$E14) | R14: =IF($A14="","",J14*$E14) | S14: =IF($A14="","",H14*$F14) | T14: =IF($A14="","",I14*$F14) | U14: =IF($A14="","",J14*$F14) | V14: =IF($A14="","",P14*(1-$G14)+S14*$L14) | W14: =IF($A14="","",Q14*(1-$G14)+T14*$L14) | X14: =IF($A14="","",R14*(1-$G14)+U14*$L14) | Y14: =IF($A14="","",(P14*60*LoadPeriods!$E$4*((1-$G14)*$M14+$G14*$N14)+S14*60*LoadPeriods!$E$4*$O14)/1000000) | Z14: =IF($A14="","",(Q14*60*LoadPeriods!$E$5*((1-$G14)*$M14+$G14*$N14)+T14*60*LoadPeriods!$E$5*$O14)/1000000) | AA14: =IF($A14="","",(R14*60*LoadPeriods!$E$6*((1-$G14)*$M14+$G14*$N14)+U14*60*LoadPeriods!$E$6*$O14)/1000000) | AB14: =IF($A14="","",SUM(Y14:AA14)) | AC14: =IF($A14="","",SUMPRODUCT(P14:R14,60*TRANSPOSE(LoadPeriods!$E$4:$E$6))) | AD14: =IF($A14="","",SUMPRODUCT(S14:U14,60*TRANSPOSE(LoadPeriods!$E$4:$E$6))) | AE14: =IF($A14="","",MAX(H14:J14)) | AF14: =IF($A14="","",MAX(P14+S14,Q14+T14,R14+U14)) | AG14: =IF($A14="","",MAX(V14:X14)) | AH14: =IF($A14="","",AG14/K14) | AI14: =IF($A14="","",IF(AH14=0,0,IF(AH14<=IF($D14="Regional",INDEX(Catalog!$F$4:$F$23,MATCH($B14,Catalog!$A$4:$A$23,0)),INDEX(Catalog!$D$4:$D$23,MATCH($B14,Catalog!$A$4:$A$23,0))),IF($D14="Regional",INDEX(Catalog!$F$4:$F$23,MATCH($B14,Catalog!$A$4:$A$23,0)),INDEX(Catalog!$D$4:$D$23,MATCH($B14,Catalog!$A$4:$A$23,0))),IF($D14="Regional",INDEX(Catalog!$F$4:$F$23,MATCH($B14,Catalog!$A$4:$A$23,0)),INDEX(Catalog!$D$4:$D$23,MATCH($B14,Catalog!$A$4:$A$23,0)))+CEILING(AH14-IF($D14="Regional",INDEX(Catalog!$F$4:$F$23,MATCH($B14,Catalog!$A$4:$A$23,0)),INDEX(Catalog!$D$4:$D$23,MATCH($B14,Catalog!$A$4:$A$23,0))),IF($D14="Regional",INDEX(Catalog!$G$4:$G$23,MATCH($B14,Catalog!$A$4:$A$23,0)),INDEX(Catalog!$E$4:$E$23,MATCH($B14,Catalog!$A$4:$A$23,0)))))))
A15: =IF(UseCases!A15="","",UseCases!A15) | B15: =IF($A15="","",UseCases!B15) | C15: =IF($A15="","",UseCases!C15) | D15: =IF($A15="","",UseCases!D15) | E15: =IF($A15="","",UseCases!E15) | F15: =IF($A15="","",UseCases!F15) | G15: =IF($A15="","",UseCases!G15) | H15: =IF($A15="","",N(UseCases!H15)) | I15: =IF($A15="","",N(UseCases!I15)) | J15: =IF($A15="","",N(UseCases!J15)) | K15: =IF($A15="","",INDEX(Catalog!$B$4:$B$23,MATCH($B15,Catalog!$A$4:$A$23,0))) | L15: =IF($A15="","",INDEX(Catalog!$C$4:$C$23,MATCH($B15,Catalog!$A$4:$A$23,0))) | M15: =IF($A15="","",INDEX(Catalog!$H$4:$H$23,MATCH($B15,Catalog!$A$4:$A$23,0))*INDEX(Catalog!$B$35:$B$37,MATCH($C15,Catalog!$A$35:$A$37,0))) | N15: =IF($A15="","",INDEX(Catalog!$I$4:$I$23,MATCH($B15,Catalog!$A$4:$A$23,0))*INDEX(Catalog!$B$35:$B$37,MATCH($C15,Catalog!$A$35:$A$37,0))) | O15: =IF($A15="","",INDEX(Catalog!$J$4:$J$23,MATCH($B15,Catalog!$A$4:$A$23,0))*INDEX(Catalog!$B$35:$B$37,MATCH($C15,Catalog!$A$35:$A$37,0))) | P15: =IF($A15="","",H15*$E15) | Q15: =IF($A15="","",I15*$E15) | R15: =IF($A15="","",J15*$E15) | S15: =IF($A15="","",H15*$F15) | T15: =IF($A15="","",I15*$F15) | U15: =IF($A15="","",J15*$F15) | V15: =IF($A15="","",P15*(1-$G15)+S15*$L15) | W15: =IF($A15="","",Q15*(1-$G15)+T15*$L15) | X15: =IF($A15="","",R15*(1-$G15)+U15*$L15) | Y15: =IF($A15="","",(P15*60*LoadPeriods!$E$4*((1-$G15)*$M15+$G15*$N15)+S15*60*LoadPeriods!$E$4*$O15)/1000000) | Z15: =IF($A15="","",(Q15*60*LoadPeriods!$E$5*((1-$G15)*$M15+$G15*$N15)+T15*60*LoadPeriods!$E$5*$O15)/1000000) | AA15: =IF($A15="","",(R15*60*LoadPeriods!$E$6*((1-$G15)*$M15+$G15*$N15)+U15*60*LoadPeriods!$E$6*$O15)/1000000) | AB15: =IF($A15="","",SUM(Y15:AA15)) | AC15: =IF($A15="","",SUMPRODUCT(P15:R15,60*TRANSPOSE(LoadPeriods!$E$4:$E$6))) | AD15: =IF($A15="","",SUMPRODUCT(S15:U15,60*TRANSPOSE(LoadPeriods!$E$4:$E$6))) | AE15: =IF($A15="","",MAX(H15:J15)) | AF15: =IF($A15="","",MAX(P15+S15,Q15+T15,R15+U15)) | AG15: =IF($A15="","",MAX(V15:X15)) | AH15: =IF($A15="","",AG15/K15) | AI15: =IF($A15="","",IF(AH15=0,0,IF(AH15<=IF($D15="Regional",INDEX(Catalog!$F$4:$F$23,MATCH($B15,Catalog!$A$4:$A$23,0)),INDEX(Catalog!$D$4:$D$23,MATCH($B15,Catalog!$A$4:$A$23,0))),IF($D15="Regional",INDEX(Catalog!$F$4:$F$23,MATCH($B15,Catalog!$A$4:$A$23,0)),INDEX(Catalog!$D$4:$D$23,MATCH($B15,Catalog!$A$4:$A$23,0))),IF($D15="Regional",INDEX(Catalog!$F$4:$F$23,MATCH($B15,Catalog!$A$4:$A$23,0)),INDEX(Catalog!$D$4:$D$23,MATCH($B15,Catalog!$A$4:$A$23,0)))+CEILING(AH15-IF($D15="Regional",INDEX(Catalog!$F$4:$F$23,MATCH($B15,Catalog!$A$4:$A$23,0)),INDEX(Catalog!$D$4:$D$23,MATCH($B15,Catalog!$A$4:$A$23,0))),IF($D15="Regional",INDEX(Catalog!$G$4:$G$23,MATCH($B15,Catalog!$A$4:$A$23,0)),INDEX(Catalog!$E$4:$E$23,MATCH($B15,Catalog!$A$4:$A$23,0)))))))
... A23: =IF(UseCases!A23="","",UseCases!A23) | B23: =IF($A23="","",UseCases!B23) | C23: =IF($A23="","",UseCases!C23) | D23: =IF($A23="","",UseCases!D23) | E23: =IF($A23="","",UseCases!E23) | F23: =IF($A23="","",UseCases!F23) | G23: =IF($A23="","",UseCases!G23) | H23: =IF($A23="","",N(UseCases!H23)) | I23: =IF($A23="","",N(UseCases!I23)) | J23: =IF($A23="","",N(UseCases!J23)) | K23: =IF($A23="","",INDEX(Catalog!$B$4:$B$23,MATCH($B23,Catalog!$A$4:$A$23,0))) | L23: =IF($A23="","",INDEX(Catalog!$C$4:$C$23,MATCH($B23,Catalog!$A$4:$A$23,0))) | M23: =IF($A23="","",INDEX(Catalog!$H$4:$H$23,MATCH($B23,Catalog!$A$4:$A$23,0))*INDEX(Catalog!$B$35:$B$37,MATCH($C23,Catalog!$A$35:$A$37,0))) | N23: =IF($A23="","",INDEX(Catalog!$I$4:$I$23,MATCH($B23,Catalog!$A$4:$A$23,0))*INDEX(Catalog!$B$35:$B$37,MATCH($C23,Catalog!$A$35:$A$37,0))) | O23: =IF($A23="","",INDEX(Catalog!$J$4:$J$23,MATCH($B23,Catalog!$A$4:$A$23,0))*INDEX(Catalog!$B$35:$B$37,MATCH($C23,Catalog!$A$35:$A$37,0))) | P23: =IF($A23="","",H23*$E23) | Q23: =IF($A23="","",I23*$E23) | R23: =IF($A23="","",J23*$E23) | S23: =IF($A23="","",H23*$F23) | T23: =IF($A23="","",I23*$F23) | U23: =IF($A23="","",J23*$F23) | V23: =IF($A23="","",P23*(1-$G23)+S23*$L23) | W23: =IF($A23="","",Q23*(1-$G23)+T23*$L23) | X23: =IF($A23="","",R23*(1-$G23)+U23*$L23) | Y23: =IF($A23="","",(P23*60*LoadPeriods!$E$4*((1-$G23)*$M23+$G23*$N23)+S23*60*LoadPeriods!$E$4*$O23)/1000000) | Z23: =IF($A23="","",(Q23*60*LoadPeriods!$E$5*((1-$G23)*$M23+$G23*$N23)+T23*60*LoadPeriods!$E$5*$O23)/1000000) | AA23: =IF($A23="","",(R23*60*LoadPeriods!$E$6*((1-$G23)*$M23+$G23*$N23)+U23*60*LoadPeriods!$E$6*$O23)/1000000) | AB23: =IF($A23="","",SUM(Y23:AA23)) | AC23: =IF($A23="","",SUMPRODUCT(P23:R23,60*TRANSPOSE(LoadPeriods!$E$4:$E$6))) | AD23: =IF($A23="","",SUMPRODUCT(S23:U23,60*TRANSPOSE(LoadPeriods!$E$4:$E$6))) | AE23: =IF($A23="","",MAX(H23:J23)) | AF23: =IF($A23="","",MAX(P23+S23,Q23+T23,R23+U23)) | AG23: =IF($A23="","",MAX(V23:X23)) | AH23: =IF($A23="","",AG23/K23) | AI23: =IF($A23="","",IF(AH23=0,0,IF(AH23<=IF($D23="Regional",INDEX(Catalog!$F$4:$F$23,MATCH($B23,Catalog!$A$4:$A$23,0)),INDEX(Catalog!$D$4:$D$23,MATCH($B23,Catalog!$A$4:$A$23,0))),IF($D23="Regional",INDEX(Catalog!$F$4:$F$23,MATCH($B23,Catalog!$A$4:$A$23,0)),INDEX(Catalog!$D$4:$D$23,MATCH($B23,Catalog!$A$4:$A$23,0))),IF($D23="Regional",INDEX(Catalog!$F$4:$F$23,MATCH($B23,Catalog!$A$4:$A$23,0)),INDEX(Catalog!$D$4:$D$23,MATCH($B23,Catalog!$A$4:$A$23,0)))+CEILING(AH23-IF($D23="Regional",INDEX(Catalog!$F$4:$F$23,MATCH($B23,Catalog!$A$4:$A$23,0)),INDEX(Catalog!$D$4:$D$23,MATCH($B23,Catalog!$A$4:$A$23,0))),IF($D23="Regional",INDEX(Catalog!$G$4:$G$23,MATCH($B23,Catalog!$A$4:$A$23,0)),INDEX(Catalog!$E$4:$E$23,MATCH($B23,Catalog!$A$4:$A$23,0)))))))

Sheet Summary
A1: PTU deployment groups & PayGO vs PTU comparison (auto). Groups = model x PTU deployment; sizing assumes coincident peaks.
A3: Model | B3: PTU deployment | C3: # use cases | D3: Peak norm TPM | E3: Exact PTUs | F3: PTUs to deploy | G3: Utilization | H3: PayGO $/mo | I3: PTU hourly $/mo | J3: PTU monthly-resv $/mo | K3: PTU yearly-resv $/mo | L3: Cheaper (vs mo-resv)
A4: =Catalog!A4 -> gpt-5.5 | B4: Global | C4: =COUNTIFS(Calcs!$B$4:$B$23,$A4,Calcs!$D$4:$D$23,$B4,Calcs!$A$4:$A$23,"<>") -> 0 | D4: =IF(C4=0,0,MAX(SUMIFS(Calcs!$V$4:$V$23,Calcs!$B$4:$B$23,$A4,Calcs!$D$4:$D$23,$B4),SUMIFS(Calcs!$W$4:$W$23,Calcs!$B$4:$B$23,$A4,Calcs!$D$4:$D$23,$B4),SUMIFS(Calcs!$X$4:$X$23,Calcs!$B$4:$B$23,$A4,Calcs!$D$4:$D$23,$B4))) -> 0 | E4: =IF(C4=0,0,D4/Catalog!B4) -> 0 | F4: =IF(E4=0,0,IF(E4<=IF($B4="Regional",Catalog!F4,Catalog!D4),IF($B4="Regional",Catalog!F4,Catalog!D4),IF($B4="Regional",Catalog!F4,Catalog!D4)+CEILING(E4-IF($B4="Regional",Catalog!F4,Catalog!D4),IF($B4="Regional",Catalog!G4,Catalog!E4)))) -> 0 | G4: =IF(F4=0,"",(SUMIFS(Calcs!$V$4:$V$23,Calcs!$B$4:$B$23,$A4,Calcs!$D$4:$D$23,$B4)*LoadPeriods!$E$4+SUMIFS(Calcs!$W$4:$W$23,Calcs!$B$4:$B$23,$A4,Calcs!$D$4:$D$23,$B4)*LoadPeriods!$E$5+SUMIFS(Calcs!$X$4:$X$23,Calcs!$B$4:$B$23,$A4,Calcs!$D$4:$D$23,$B4)*LoadPeriods!$E$6)/(F4*Catalog!B4*Catalog!$B$40)) | H4: =IF(C4=0,0,SUMIFS(Calcs!$AB$4:$AB$23,Calcs!$B$4:$B$23,$A4,Calcs!$D$4:$D$23,$B4)) -> 0 | I4: =IF(F4=0,0,F4*INDEX(Catalog!$B$28:$B$30,MATCH($B4,Catalog!$A$28:$A$30,0))*Catalog!$B$40) -> 0 | J4: =IF(F4=0,0,F4*INDEX(Catalog!$C$28:$C$30,MATCH($B4,Catalog!$A$28:$A$30,0))) -> 0 | K4: =IF(F4=0,0,F4*INDEX(Catalog!$D$28:$D$30,MATCH($B4,Catalog!$A$28:$A$30,0))/12) -> 0 | L4: =IF(C4=0,"",IF(J4<=H4,"PTU","PayGO"))
A5: =Catalog!A4 -> gpt-5.5 | B5: Data Zone | C5: =COUNTIFS(Calcs!$B$4:$B$23,$A5,Calcs!$D$4:$D$23,$B5,Calcs!$A$4:$A$23,"<>") -> 0 | D5: =IF(C5=0,0,MAX(SUMIFS(Calcs!$V$4:$V$23,Calcs!$B$4:$B$23,$A5,Calcs!$D$4:$D$23,$B5),SUMIFS(Calcs!$W$4:$W$23,Calcs!$B$4:$B$23,$A5,Calcs!$D$4:$D$23,$B5),SUMIFS(Calcs!$X$4:$X$23,Calcs!$B$4:$B$23,$A5,Calcs!$D$4:$D$23,$B5))) -> 0 | E5: =IF(C5=0,0,D5/Catalog!B4) -> 0 | F5: =IF(E5=0,0,IF(E5<=IF($B5="Regional",Catalog!F4,Catalog!D4),IF($B5="Regional",Catalog!F4,Catalog!D4),IF($B5="Regional",Catalog!F4,Catalog!D4)+CEILING(E5-IF($B5="Regional",Catalog!F4,Catalog!D4),IF($B5="Regional",Catalog!G4,Catalog!E4)))) -> 0 | G5: =IF(F5=0,"",(SUMIFS(Calcs!$V$4:$V$23,Calcs!$B$4:$B$23,$A5,Calcs!$D$4:$D$23,$B5)*LoadPeriods!$E$4+SUMIFS(Calcs!$W$4:$W$23,Calcs!$B$4:$B$23,$A5,Calcs!$D$4:$D$23,$B5)*LoadPeriods!$E$5+SUMIFS(Calcs!$X$4:$X$23,Calcs!$B$4:$B$23,$A5,Calcs!$D$4:$D$23,$B5)*LoadPeriods!$E$6)/(F5*Catalog!B4*Catalog!$B$40)) | H5: =IF(C5=0,0,SUMIFS(Calcs!$AB$4:$AB$23,Calcs!$B$4:$B$23,$A5,Calcs!$D$4:$D$23,$B5)) -> 0 | I5: =IF(F5=0,0,F5*INDEX(Catalog!$B$28:$B$30,MATCH($B5,Catalog!$A$28:$A$30,0))*Catalog!$B$40) -> 0 | J5: =IF(F5=0,0,F5*INDEX(Catalog!$C$28:$C$30,MATCH($B5,Catalog!$A$28:$A$30,0))) -> 0 | K5: =IF(F5=0,0,F5*INDEX(Catalog!$D$28:$D$30,MATCH($B5,Catalog!$A$28:$A$30,0))/12) -> 0 | L5: =IF(C5=0,"",IF(J5<=H5,"PTU","PayGO"))
A6: =Catalog!A4 -> gpt-5.5 | B6: Regional | C6: =COUNTIFS(Calcs!$B$4:$B$23,$A6,Calcs!$D$4:$D$23,$B6,Calcs!$A$4:$A$23,"<>") -> 0 | D6: =IF(C6=0,0,MAX(SUMIFS(Calcs!$V$4:$V$23,Calcs!$B$4:$B$23,$A6,Calcs!$D$4:$D$23,$B6),SUMIFS(Calcs!$W$4:$W$23,Calcs!$B$4:$B$23,$A6,Calcs!$D$4:$D$23,$B6),SUMIFS(Calcs!$X$4:$X$23,Calcs!$B$4:$B$23,$A6,Calcs!$D$4:$D$23,$B6))) -> 0 | E6: =IF(C6=0,0,D6/Catalog!B4) -> 0 | F6: =IF(E6=0,0,IF(E6<=IF($B6="Regional",Catalog!F4,Catalog!D4),IF($B6="Regional",Catalog!F4,Catalog!D4),IF($B6="Regional",Catalog!F4,Catalog!D4)+CEILING(E6-IF($B6="Regional",Catalog!F4,Catalog!D4),IF($B6="Regional",Catalog!G4,Catalog!E4)))) -> 0 | G6: =IF(F6=0,"",(SUMIFS(Calcs!$V$4:$V$23,Calcs!$B$4:$B$23,$A6,Calcs!$D$4:$D$23,$B6)*LoadPeriods!$E$4+SUMIFS(Calcs!$W$4:$W$23,Calcs!$B$4:$B$23,$A6,Calcs!$D$4:$D$23,$B6)*LoadPeriods!$E$5+SUMIFS(Calcs!$X$4:$X$23,Calcs!$B$4:$B$23,$A6,Calcs!$D$4:$D$23,$B6)*LoadPeriods!$E$6)/(F6*Catalog!B4*Catalog!$B$40)) | H6: =IF(C6=0,0,SUMIFS(Calcs!$AB$4:$AB$23,Calcs!$B$4:$B$23,$A6,Calcs!$D$4:$D$23,$B6)) -> 0 | I6: =IF(F6=0,0,F6*INDEX(Catalog!$B$28:$B$30,MATCH($B6,Catalog!$A$28:$A$30,0))*Catalog!$B$40) -> 0 | J6: =IF(F6=0,0,F6*INDEX(Catalog!$C$28:$C$30,MATCH($B6,Catalog!$A$28:$A$30,0))) -> 0 | K6: =IF(F6=0,0,F6*INDEX(Catalog!$D$28:$D$30,MATCH($B6,Catalog!$A$28:$A$30,0))/12) -> 0 | L6: =IF(C6=0,"",IF(J6<=H6,"PTU","PayGO"))
A7: =Catalog!A5 -> gpt-5.4 | B7: Global | C7: =COUNTIFS(Calcs!$B$4:$B$23,$A7,Calcs!$D$4:$D$23,$B7,Calcs!$A$4:$A$23,"<>") -> 0 | D7: =IF(C7=0,0,MAX(SUMIFS(Calcs!$V$4:$V$23,Calcs!$B$4:$B$23,$A7,Calcs!$D$4:$D$23,$B7),SUMIFS(Calcs!$W$4:$W$23,Calcs!$B$4:$B$23,$A7,Calcs!$D$4:$D$23,$B7),SUMIFS(Calcs!$X$4:$X$23,Calcs!$B$4:$B$23,$A7,Calcs!$D$4:$D$23,$B7))) -> 0 | E7: =IF(C7=0,0,D7/Catalog!B5) -> 0 | F7: =IF(E7=0,0,IF(E7<=IF($B7="Regional",Catalog!F5,Catalog!D5),IF($B7="Regional",Catalog!F5,Catalog!D5),IF($B7="Regional",Catalog!F5,Catalog!D5)+CEILING(E7-IF($B7="Regional",Catalog!F5,Catalog!D5),IF($B7="Regional",Catalog!G5,Catalog!E5)))) -> 0 | G7: =IF(F7=0,"",(SUMIFS(Calcs!$V$4:$V$23,Calcs!$B$4:$B$23,$A7,Calcs!$D$4:$D$23,$B7)*LoadPeriods!$E$4+SUMIFS(Calcs!$W$4:$W$23,Calcs!$B$4:$B$23,$A7,Calcs!$D$4:$D$23,$B7)*LoadPeriods!$E$5+SUMIFS(Calcs!$X$4:$X$23,Calcs!$B$4:$B$23,$A7,Calcs!$D$4:$D$23,$B7)*LoadPeriods!$E$6)/(F7*Catalog!B5*Catalog!$B$40)) | H7: =IF(C7=0,0,SUMIFS(Calcs!$AB$4:$AB$23,Calcs!$B$4:$B$23,$A7,Calcs!$D$4:$D$23,$B7)) -> 0 | I7: =IF(F7=0,0,F7*INDEX(Catalog!$B$28:$B$30,MATCH($B7,Catalog!$A$28:$A$30,0))*Catalog!$B$40) -> 0 | J7: =IF(F7=0,0,F7*INDEX(Catalog!$C$28:$C$30,MATCH($B7,Catalog!$A$28:$A$30,0))) -> 0 | K7: =IF(F7=0,0,F7*INDEX(Catalog!$D$28:$D$30,MATCH($B7,Catalog!$A$28:$A$30,0))/12) -> 0 | L7: =IF(C7=0,"",IF(J7<=H7,"PTU","PayGO"))
A8: =Catalog!A5 -> gpt-5.4 | B8: Data Zone | C8: =COUNTIFS(Calcs!$B$4:$B$23,$A8,Calcs!$D$4:$D$23,$B8,Calcs!$A$4:$A$23,"<>") -> 0 | D8: =IF(C8=0,0,MAX(SUMIFS(Calcs!$V$4:$V$23,Calcs!$B$4:$B$23,$A8,Calcs!$D$4:$D$23,$B8),SUMIFS(Calcs!$W$4:$W$23,Calcs!$B$4:$B$23,$A8,Calcs!$D$4:$D$23,$B8),SUMIFS(Calcs!$X$4:$X$23,Calcs!$B$4:$B$23,$A8,Calcs!$D$4:$D$23,$B8))) -> 0 | E8: =IF(C8=0,0,D8/Catalog!B5) -> 0 | F8: =IF(E8=0,0,IF(E8<=IF($B8="Regional",Catalog!F5,Catalog!D5),IF($B8="Regional",Catalog!F5,Catalog!D5),IF($B8="Regional",Catalog!F5,Catalog!D5)+CEILING(E8-IF($B8="Regional",Catalog!F5,Catalog!D5),IF($B8="Regional",Catalog!G5,Catalog!E5)))) -> 0 | G8: =IF(F8=0,"",(SUMIFS(Calcs!$V$4:$V$23,Calcs!$B$4:$B$23,$A8,Calcs!$D$4:$D$23,$B8)*LoadPeriods!$E$4+SUMIFS(Calcs!$W$4:$W$23,Calcs!$B$4:$B$23,$A8,Calcs!$D$4:$D$23,$B8)*LoadPeriods!$E$5+SUMIFS(Calcs!$X$4:$X$23,Calcs!$B$4:$B$23,$A8,Calcs!$D$4:$D$23,$B8)*LoadPeriods!$E$6)/(F8*Catalog!B5*Catalog!$B$40)) | H8: =IF(C8=0,0,SUMIFS(Calcs!$AB$4:$AB$23,Calcs!$B$4:$B$23,$A8,Calcs!$D$4:$D$23,$B8)) -> 0 | I8: =IF(F8=0,0,F8*INDEX(Catalog!$B$28:$B$30,MATCH($B8,Catalog!$A$28:$A$30,0))*Catalog!$B$40) -> 0 | J8: =IF(F8=0,0,F8*INDEX(Catalog!$C$28:$C$30,MATCH($B8,Catalog!$A$28:$A$30,0))) -> 0 | K8: =IF(F8=0,0,F8*INDEX(Catalog!$D$28:$D$30,MATCH($B8,Catalog!$A$28:$A$30,0))/12) -> 0 | L8: =IF(C8=0,"",IF(J8<=H8,"PTU","PayGO"))
A9: =Catalog!A5 -> gpt-5.4 | B9: Regional | C9: =COUNTIFS(Calcs!$B$4:$B$23,$A9,Calcs!$D$4:$D$23,$B9,Calcs!$A$4:$A$23,"<>") -> 0 | D9: =IF(C9=0,0,MAX(SUMIFS(Calcs!$V$4:$V$23,Calcs!$B$4:$B$23,$A9,Calcs!$D$4:$D$23,$B9),SUMIFS(Calcs!$W$4:$W$23,Calcs!$B$4:$B$23,$A9,Calcs!$D$4:$D$23,$B9),SUMIFS(Calcs!$X$4:$X$23,Calcs!$B$4:$B$23,$A9,Calcs!$D$4:$D$23,$B9))) -> 0 | E9: =IF(C9=0,0,D9/Catalog!B5) -> 0 | F9: =IF(E9=0,0,IF(E9<=IF($B9="Regional",Catalog!F5,Catalog!D5),IF($B9="Regional",Catalog!F5,Catalog!D5),IF($B9="Regional",Catalog!F5,Catalog!D5)+CEILING(E9-IF($B9="Regional",Catalog!F5,Catalog!D5),IF($B9="Regional",Catalog!G5,Catalog!E5)))) -> 0 | G9: =IF(F9=0,"",(SUMIFS(Calcs!$V$4:$V$23,Calcs!$B$4:$B$23,$A9,Calcs!$D$4:$D$23,$B9)*LoadPeriods!$E$4+SUMIFS(Calcs!$W$4:$W$23,Calcs!$B$4:$B$23,$A9,Calcs!$D$4:$D$23,$B9)*LoadPeriods!$E$5+SUMIFS(Calcs!$X$4:$X$23,Calcs!$B$4:$B$23,$A9,Calcs!$D$4:$D$23,$B9)*LoadPeriods!$E$6)/(F9*Catalog!B5*Catalog!$B$40)) | H9: =IF(C9=0,0,SUMIFS(Calcs!$AB$4:$AB$23,Calcs!$B$4:$B$23,$A9,Calcs!$D$4:$D$23,$B9)) -> 0 | I9: =IF(F9=0,0,F9*INDEX(Catalog!$B$28:$B$30,MATCH($B9,Catalog!$A$28:$A$30,0))*Catalog!$B$40) -> 0 | J9: =IF(F9=0,0,F9*INDEX(Catalog!$C$28:$C$30,MATCH($B9,Catalog!$A$28:$A$30,0))) -> 0 | K9: =IF(F9=0,0,F9*INDEX(Catalog!$D$28:$D$30,MATCH($B9,Catalog!$A$28:$A$30,0))/12) -> 0 | L9: =IF(C9=0,"",IF(J9<=H9,"PTU","PayGO"))
A10: =Catalog!A6 -> gpt-5.4-mini | B10: Global | C10: =COUNTIFS(Calcs!$B$4:$B$23,$A10,Calcs!$D$4:$D$23,$B10,Calcs!$A$4:$A$23,"<>") -> 0 | D10: =IF(C10=0,0,MAX(SUMIFS(Calcs!$V$4:$V$23,Calcs!$B$4:$B$23,$A10,Calcs!$D$4:$D$23,$B10),SUMIFS(Calcs!$W$4:$W$23,Calcs!$B$4:$B$23,$A10,Calcs!$D$4:$D$23,$B10),SUMIFS(Calcs!$X$4:$X$23,Calcs!$B$4:$B$23,$A10,Calcs!$D$4:$D$23,$B10))) -> 0 | E10: =IF(C10=0,0,D10/Catalog!B6) -> 0 | F10: =IF(E10=0,0,IF(E10<=IF($B10="Regional",Catalog!F6,Catalog!D6),IF($B10="Regional",Catalog!F6,Catalog!D6),IF($B10="Regional",Catalog!F6,Catalog!D6)+CEILING(E10-IF($B10="Regional",Catalog!F6,Catalog!D6),IF($B10="Regional",Catalog!G6,Catalog!E6)))) -> 0 | G10: =IF(F10=0,"",(SUMIFS(Calcs!$V$4:$V$23,Calcs!$B$4:$B$23,$A10,Calcs!$D$4:$D$23,$B10)*LoadPeriods!$E$4+SUMIFS(Calcs!$W$4:$W$23,Calcs!$B$4:$B$23,$A10,Calcs!$D$4:$D$23,$B10)*LoadPeriods!$E$5+SUMIFS(Calcs!$X$4:$X$23,Calcs!$B$4:$B$23,$A10,Calcs!$D$4:$D$23,$B10)*LoadPeriods!$E$6)/(F10*Catalog!B6*Catalog!$B$40)) | H10: =IF(C10=0,0,SUMIFS(Calcs!$AB$4:$AB$23,Calcs!$B$4:$B$23,$A10,Calcs!$D$4:$D$23,$B10)) -> 0 | I10: =IF(F10=0,0,F10*INDEX(Catalog!$B$28:$B$30,MATCH($B10,Catalog!$A$28:$A$30,0))*Catalog!$B$40) -> 0 | J10: =IF(F10=0,0,F10*INDEX(Catalog!$C$28:$C$30,MATCH($B10,Catalog!$A$28:$A$30,0))) -> 0 | K10: =IF(F10=0,0,F10*INDEX(Catalog!$D$28:$D$30,MATCH($B10,Catalog!$A$28:$A$30,0))/12) -> 0 | L10: =IF(C10=0,"",IF(J10<=H10,"PTU","PayGO"))
A11: =Catalog!A6 -> gpt-5.4-mini | B11: Data Zone | C11: =COUNTIFS(Calcs!$B$4:$B$23,$A11,Calcs!$D$4:$D$23,$B11,Calcs!$A$4:$A$23,"<>") -> 0 | D11: =IF(C11=0,0,MAX(SUMIFS(Calcs!$V$4:$V$23,Calcs!$B$4:$B$23,$A11,Calcs!$D$4:$D$23,$B11),SUMIFS(Calcs!$W$4:$W$23,Calcs!$B$4:$B$23,$A11,Calcs!$D$4:$D$23,$B11),SUMIFS(Calcs!$X$4:$X$23,Calcs!$B$4:$B$23,$A11,Calcs!$D$4:$D$23,$B11))) -> 0 | E11: =IF(C11=0,0,D11/Catalog!B6) -> 0 | F11: =IF(E11=0,0,IF(E11<=IF($B11="Regional",Catalog!F6,Catalog!D6),IF($B11="Regional",Catalog!F6,Catalog!D6),IF($B11="Regional",Catalog!F6,Catalog!D6)+CEILING(E11-IF($B11="Regional",Catalog!F6,Catalog!D6),IF($B11="Regional",Catalog!G6,Catalog!E6)))) -> 0 | G11: =IF(F11=0,"",(SUMIFS(Calcs!$V$4:$V$23,Calcs!$B$4:$B$23,$A11,Calcs!$D$4:$D$23,$B11)*LoadPeriods!$E$4+SUMIFS(Calcs!$W$4:$W$23,Calcs!$B$4:$B$23,$A11,Calcs!$D$4:$D$23,$B11)*LoadPeriods!$E$5+SUMIFS(Calcs!$X$4:$X$23,Calcs!$B$4:$B$23,$A11,Calcs!$D$4:$D$23,$B11)*LoadPeriods!$E$6)/(F11*Catalog!B6*Catalog!$B$40)) | H11: =IF(C11=0,0,SUMIFS(Calcs!$AB$4:$AB$23,Calcs!$B$4:$B$23,$A11,Calcs!$D$4:$D$23,$B11)) -> 0 | I11: =IF(F11=0,0,F11*INDEX(Catalog!$B$28:$B$30,MATCH($B11,Catalog!$A$28:$A$30,0))*Catalog!$B$40) -> 0 | J11: =IF(F11=0,0,F11*INDEX(Catalog!$C$28:$C$30,MATCH($B11,Catalog!$A$28:$A$30,0))) -> 0 | K11: =IF(F11=0,0,F11*INDEX(Catalog!$D$28:$D$30,MATCH($B11,Catalog!$A$28:$A$30,0))/12) -> 0 | L11: =IF(C11=0,"",IF(J11<=H11,"PTU","PayGO"))
A12: =Catalog!A6 -> gpt-5.4-mini | B12: Regional | C12: =COUNTIFS(Calcs!$B$4:$B$23,$A12,Calcs!$D$4:$D$23,$B12,Calcs!$A$4:$A$23,"<>") -> 0 | D12: =IF(C12=0,0,MAX(SUMIFS(Calcs!$V$4:$V$23,Calcs!$B$4:$B$23,$A12,Calcs!$D$4:$D$23,$B12),SUMIFS(Calcs!$W$4:$W$23,Calcs!$B$4:$B$23,$A12,Calcs!$D$4:$D$23,$B12),SUMIFS(Calcs!$X$4:$X$23,Calcs!$B$4:$B$23,$A12,Calcs!$D$4:$D$23,$B12))) -> 0 | E12: =IF(C12=0,0,D12/Catalog!B6) -> 0 | F12: =IF(E12=0,0,IF(E12<=IF($B12="Regional",Catalog!F6,Catalog!D6),IF($B12="Regional",Catalog!F6,Catalog!D6),IF($B12="Regional",Catalog!F6,Catalog!D6)+CEILING(E12-IF($B12="Regional",Catalog!F6,Catalog!D6),IF($B12="Regional",Catalog!G6,Catalog!E6)))) -> 0 | G12: =IF(F12=0,"",(SUMIFS(Calcs!$V$4:$V$23,Calcs!$B$4:$B$23,$A12,Calcs!$D$4:$D$23,$B12)*LoadPeriods!$E$4+SUMIFS(Calcs!$W$4:$W$23,Calcs!$B$4:$B$23,$A12,Calcs!$D$4:$D$23,$B12)*LoadPeriods!$E$5+SUMIFS(Calcs!$X$4:$X$23,Calcs!$B$4:$B$23,$A12,Calcs!$D$4:$D$23,$B12)*LoadPeriods!$E$6)/(F12*Catalog!B6*Catalog!$B$40)) | H12: =IF(C12=0,0,SUMIFS(Calcs!$AB$4:$AB$23,Calcs!$B$4:$B$23,$A12,Calcs!$D$4:$D$23,$B12)) -> 0 | I12: =IF(F12=0,0,F12*INDEX(Catalog!$B$28:$B$30,MATCH($B12,Catalog!$A$28:$A$30,0))*Catalog!$B$40) -> 0 | J12: =IF(F12=0,0,F12*INDEX(Catalog!$C$28:$C$30,MATCH($B12,Catalog!$A$28:$A$30,0))) -> 0 | K12: =IF(F12=0,0,F12*INDEX(Catalog!$D$28:$D$30,MATCH($B12,Catalog!$A$28:$A$30,0))/12) -> 0 | L12: =IF(C12=0,"",IF(J12<=H12,"PTU","PayGO"))
A13: =Catalog!A7 -> gpt-5.2 | B13: Global | C13: =COUNTIFS(Calcs!$B$4:$B$23,$A13,Calcs!$D$4:$D$23,$B13,Calcs!$A$4:$A$23,"<>") -> 0 | D13: =IF(C13=0,0,MAX(SUMIFS(Calcs!$V$4:$V$23,Calcs!$B$4:$B$23,$A13,Calcs!$D$4:$D$23,$B13),SUMIFS(Calcs!$W$4:$W$23,Calcs!$B$4:$B$23,$A13,Calcs!$D$4:$D$23,$B13),SUMIFS(Calcs!$X$4:$X$23,Calcs!$B$4:$B$23,$A13,Calcs!$D$4:$D$23,$B13))) -> 0 | E13: =IF(C13=0,0,D13/Catalog!B7) -> 0 | F13: =IF(E13=0,0,IF(E13<=IF($B13="Regional",Catalog!F7,Catalog!D7),IF($B13="Regional",Catalog!F7,Catalog!D7),IF($B13="Regional",Catalog!F7,Catalog!D7)+CEILING(E13-IF($B13="Regional",Catalog!F7,Catalog!D7),IF($B13="Regional",Catalog!G7,Catalog!E7)))) -> 0 | G13: =IF(F13=0,"",(SUMIFS(Calcs!$V$4:$V$23,Calcs!$B$4:$B$23,$A13,Calcs!$D$4:$D$23,$B13)*LoadPeriods!$E$4+SUMIFS(Calcs!$W$4:$W$23,Calcs!$B$4:$B$23,$A13,Calcs!$D$4:$D$23,$B13)*LoadPeriods!$E$5+SUMIFS(Calcs!$X$4:$X$23,Calcs!$B$4:$B$23,$A13,Calcs!$D$4:$D$23,$B13)*LoadPeriods!$E$6)/(F13*Catalog!B7*Catalog!$B$40)) | H13: =IF(C13=0,0,SUMIFS(Calcs!$AB$4:$AB$23,Calcs!$B$4:$B$23,$A13,Calcs!$D$4:$D$23,$B13)) -> 0 | I13: =IF(F13=0,0,F13*INDEX(Catalog!$B$28:$B$30,MATCH($B13,Catalog!$A$28:$A$30,0))*Catalog!$B$40) -> 0 | J13: =IF(F13=0,0,F13*INDEX(Catalog!$C$28:$C$30,MATCH($B13,Catalog!$A$28:$A$30,0))) -> 0 | K13: =IF(F13=0,0,F13*INDEX(Catalog!$D$28:$D$30,MATCH($B13,Catalog!$A$28:$A$30,0))/12) -> 0 | L13: =IF(C13=0,"",IF(J13<=H13,"PTU","PayGO"))
A14: =Catalog!A7 -> gpt-5.2 | B14: Data Zone | C14: =COUNTIFS(Calcs!$B$4:$B$23,$A14,Calcs!$D$4:$D$23,$B14,Calcs!$A$4:$A$23,"<>") -> 0 | D14: =IF(C14=0,0,MAX(SUMIFS(Calcs!$V$4:$V$23,Calcs!$B$4:$B$23,$A14,Calcs!$D$4:$D$23,$B14),SUMIFS(Calcs!$W$4:$W$23,Calcs!$B$4:$B$23,$A14,Calcs!$D$4:$D$23,$B14),SUMIFS(Calcs!$X$4:$X$23,Calcs!$B$4:$B$23,$A14,Calcs!$D$4:$D$23,$B14))) -> 0 | E14: =IF(C14=0,0,D14/Catalog!B7) -> 0 | F14: =IF(E14=0,0,IF(E14<=IF($B14="Regional",Catalog!F7,Catalog!D7),IF($B14="Regional",Catalog!F7,Catalog!D7),IF($B14="Regional",Catalog!F7,Catalog!D7)+CEILING(E14-IF($B14="Regional",Catalog!F7,Catalog!D7),IF($B14="Regional",Catalog!G7,Catalog!E7)))) -> 0 | G14: =IF(F14=0,"",(SUMIFS(Calcs!$V$4:$V$23,Calcs!$B$4:$B$23,$A14,Calcs!$D$4:$D$23,$B14)*LoadPeriods!$E$4+SUMIFS(Calcs!$W$4:$W$23,Calcs!$B$4:$B$23,$A14,Calcs!$D$4:$D$23,$B14)*LoadPeriods!$E$5+SUMIFS(Calcs!$X$4:$X$23,Calcs!$B$4:$B$23,$A14,Calcs!$D$4:$D$23,$B14)*LoadPeriods!$E$6)/(F14*Catalog!B7*Catalog!$B$40)) | H14: =IF(C14=0,0,SUMIFS(Calcs!$AB$4:$AB$23,Calcs!$B$4:$B$23,$A14,Calcs!$D$4:$D$23,$B14)) -> 0 | I14: =IF(F14=0,0,F14*INDEX(Catalog!$B$28:$B$30,MATCH($B14,Catalog!$A$28:$A$30,0))*Catalog!$B$40) -> 0 | J14: =IF(F14=0,0,F14*INDEX(Catalog!$C$28:$C$30,MATCH($B14,Catalog!$A$28:$A$30,0))) -> 0 | K14: =IF(F14=0,0,F14*INDEX(Catalog!$D$28:$D$30,MATCH($B14,Catalog!$A$28:$A$30,0))/12) -> 0 | L14: =IF(C14=0,"",IF(J14<=H14,"PTU","PayGO"))
A15: =Catalog!A7 -> gpt-5.2 | B15: Regional | C15: =COUNTIFS(Calcs!$B$4:$B$23,$A15,Calcs!$D$4:$D$23,$B15,Calcs!$A$4:$A$23,"<>") -> 0 | D15: =IF(C15=0,0,MAX(SUMIFS(Calcs!$V$4:$V$23,Calcs!$B$4:$B$23,$A15,Calcs!$D$4:$D$23,$B15),SUMIFS(Calcs!$W$4:$W$23,Calcs!$B$4:$B$23,$A15,Calcs!$D$4:$D$23,$B15),SUMIFS(Calcs!$X$4:$X$23,Calcs!$B$4:$B$23,$A15,Calcs!$D$4:$D$23,$B15))) -> 0 | E15: =IF(C15=0,0,D15/Catalog!B7) -> 0 | F15: =IF(E15=0,0,IF(E15<=IF($B15="Regional",Catalog!F7,Catalog!D7),IF($B15="Regional",Catalog!F7,Catalog!D7),IF($B15="Regional",Catalog!F7,Catalog!D7)+CEILING(E15-IF($B15="Regional",Catalog!F7,Catalog!D7),IF($B15="Regional",Catalog!G7,Catalog!E7)))) -> 0 | G15: =IF(F15=0,"",(SUMIFS(Calcs!$V$4:$V$23,Calcs!$B$4:$B$23,$A15,Calcs!$D$4:$D$23,$B15)*LoadPeriods!$E$4+SUMIFS(Calcs!$W$4:$W$23,Calcs!$B$4:$B$23,$A15,Calcs!$D$4:$D$23,$B15)*LoadPeriods!$E$5+SUMIFS(Calcs!$X$4:$X$23,Calcs!$B$4:$B$23,$A15,Calcs!$D$4:$D$23,$B15)*LoadPeriods!$E$6)/(F15*Catalog!B7*Catalog!$B$40)) | H15: =IF(C15=0,0,SUMIFS(Calcs!$AB$4:$AB$23,Calcs!$B$4:$B$23,$A15,Calcs!$D$4:$D$23,$B15)) -> 0 | I15: =IF(F15=0,0,F15*INDEX(Catalog!$B$28:$B$30,MATCH($B15,Catalog!$A$28:$A$30,0))*Catalog!$B$40) -> 0 | J15: =IF(F15=0,0,F15*INDEX(Catalog!$C$28:$C$30,MATCH($B15,Catalog!$A$28:$A$30,0))) -> 0 | K15: =IF(F15=0,0,F15*INDEX(Catalog!$D$28:$D$30,MATCH($B15,Catalog!$A$28:$A$30,0))/12) -> 0 | L15: =IF(C15=0,"",IF(J15<=H15,"PTU","PayGO"))
